Workbook

Sheet Original Data
A1: Variable Name | B1: Value | C1: P | D1: R | E1: A1 | F1: A2 | G1: A3 | H1: B1 | I1: B2 | J1: B3 | K1: C1 | L1: C2 | M1: C3
A2: P | B2: Precinct Name | C2: 1000 | D2: 640 | E2: 15 | F2: 14 | G2: 2 | H2: 42 | I2: 66 | J2: 15 | K2: 14 | L2: 6 | M2: 27
A3: R | B3: Registered | C3: 1001 | D3: 1053 | E3: 15 | F3: 22 | G3: 14 | H3: 37 | I3: 76 | J3: 22 | K3: 14 | L3: 11 | M3: 23
A4: A1 | B4: Hyt Early | C4: 1004 | D4: 1917 | E4: 7 | F4: 17 | G4: 9 | H4: 21 | I4: 72 | J4: 24 | K4: 6 | L4: 11 | M4: 63
A5: A2 | B5: Hyt Mail | C5: 1005 | D5: 1599 | E5: 14 | F5: 26 | G5: 11 | H5: 65 | I5: 130 | J5: 29 | K5: 27 | L5: 10 | M5: 62
A6: A3 | B6: Hyt EDV | C6: 1006 | D6: 1548 | E6: 5 | F6: 27 | G6: 6 | H6: 33 | I6: 68 | J6: 27 | K6: 16 | L6: 6 | M6: 39
A7: B1 | B7: McMahill Early | C7: 1007 | D7: 2681 | E7: 14 | F7: 24 | G7: 9 | H7: 36 | I7: 102 | J7: 33 | K7: 17 | L7: 15 | M7: 47
A8: B2 | B8: McMahill Mail | C8: 1008 | D8: 3439 | E8: 15 | F8: 38 | G8: 25 | H8: 65 | I8: 139 | J8: 35 | K8: 27 | L8: 16 | M8: 64
A9: B3 | B9: McMahill EDV | C9: 1009 | D9: 1380 | E9: 23 | F9: 25 | G9: 29 | H9: 67 | I9: 118 | J9: 46 | K9: 24 | L9: 21 | M9: 51
A10: C1 | B10: Roberts Early | C10: 1012 | D10: 1883 | E10: 23 | F10: 57 | G10: 28 | H10: 82 | I10: 244 | J10: 69 | K10: 35 | L10: 22 | M10: 121
A11: C2 | B11: Roberts Mail | C11: 1015 | D11: 2510 | E11: 34 | F11: 48 | G11: 19 | H11: 69 | I11: 155 | J11: 42 | K11: 14 | L11: 20 | M11: 78
A12: C3 | B12: Roberts EDV | C12: 1016 | D12: 485 | E12: 4 | F12: 15 | G12: 12 | H12: 21 | I12: 47 | J12: 17 | K12: 7 | L12: 2 | M12: 28
C13: 1038 | D13: 2098 | E13: 14 | F13: 38 | G13: 10 | H13: 59 | I13: 120 | J13: 27 | K13: 13 | L13: 9 | M13: 49
C14: 1039 | D14: 3242 | E14: 27 | F14: 74 | G14: 33 | H14: 143 | I14: 271 | J14: 73 | K14: 38 | L14: 22 | M14: 116
C15: 1063 | D15: 1412 | E15: 12 | F15: 27 | G15: 24 | H15: 49 | I15: 115 | J15: 48 | K15: 21 | L15: 7 | M15: 46
C16: 1074 | D16: 2203 | E16: 6 | F16: 47 | G16: 20 | H16: 37 | I16: 230 | J16: 77 | K16: 11 | L16: 19 | M16: 84
C17: 1302 | D17: 3655 | E17: 32 | F17: 42 | G17: 14 | H17: 85 | I17: 232 | J17: 60 | K17: 31 | L17: 38 | M17: 81
C18: 1304 | D18: 2660 | E18: 19 | F18: 40 | G18: 30 | H18: 53 | I18: 145 | J18: 35 | K18: 28 | L18: 13 | M18: 64
C19: 1307 | D19: 2027 | E19: 29 | F19: 30 | G19: 27 | H19: 66 | I19: 142 | J19: 44 | K19: 18 | L19: 18 | M19: 63
C20: 1318 | D20: 1739 | E20: 14 | F20: 20 | G20: 12 | H20: 29 | I20: 71 | J20: 29 | K20: 5 | L20: 6 | M20: 28
C21: 1327 | D21: 2196 | E21: 19 | F21: 22 | G21: 15 | H21: 33 | I21: 85 | J21: 23 | K21: 18 | L21: 13 | M21: 36
C22: 1328 | D22: 1757 | E22: 11 | F22: 22 | G22: 13 | H22: 38 | I22: 105 | J22: 25 | K22: 20 | L22: 8 | M22: 45
C23: 1330 | D23: 1937 | E23: 27 | F23: 41 | G23: 29 | H23: 69 | I23: 130 | J23: 66 | K23: 21 | L23: 12 | M23: 43
C24: 1331 | D24: 1777 | E24: 11 | F24: 30 | G24: 24 | H24: 27 | I24: 86 | J24: 31 | K24: 11 | L24: 6 | M24: 44
... C599: 7730 | D599: 2494 | E599: 12 | F599: 52 | G599: 43 | H599: 62 | I599: 208 | J599: 47 | K599: 31 | L599: 18 | M599: 95

Sheet Restored Results
A1: Variable Name | B1: Value | D1: P | E1: R | F1: A1 | G1: A2 | H1: A3 | I1: B1 | J1: B2 | K1: B3 | L1: C1 | M1: C2 | N1: C3 | O1: Total | P1: Relative Restore-> | Q1: A1 | R1: A2 | S1: A3 | T1: B1 | U1: B2 | V1: B3 | W1: C1 | X1: C2 | Y1: C3 | Z1: Total | AA1: Great Scale | AB1: Final Restore--> | AC1: A1 | AD1: A2 | AE1: A3 | AF1: B1 | AG1: B2 | AH1: B3 | AI1: C1 | AJ1: C2 | AK1: C3 | AL1: Total
A2: P | B2: Precinct Name | D2: 1000 | E2: 640 | F2: 15 | G2: 14 | H2: 2 | I2: 42 | J2: 66 | K2: 15 | L2: 14 | M2: 6 | N2: 27 | O2: =SUM(F2:N2) -> 201 | Q2: ='X,Y restore'!G2 -> 15 | R2: ='X,Y restore'!H2 -> 7 | S2: ='X,Y restore'!I2 -> 2 | T2: ='X,Y restore'!AI2 -> 10 | U2: ='X,Y restore'!AG2 -> 4 | V2: ='X,Y restore'!AJ2 -> 0 | W2: ='X,Y restore'!M2 -> 13 | X2: ='X,Y restore'!N2 -> 6 | Y2: ='X,Y restore'!O2 -> 1 | Z2: =SUM(Q2:Y2) -> 58 | AA2: =O2/Z2 -> 3.4655172 | AC2: =ROUND($AA2*Q2,0) -> 52 | AD2: =ROUND($AA2*R2,0) -> 24 | AE2: =ROUND($AA2*S2,0) -> 7 | AF2: =ROUND($AA2*T2,0) -> 35 | AG2: =ROUND($AA2*U2,0) -> 14 | AH2: =ROUND($AA2*V2,0) -> 0 | AI2: =ROUND($AA2*W2,0) -> 45 | AJ2: =ROUND($AA2*X2,0) -> 21 | AK2: =ROUND($AA2*Y2,0) -> 3 | AL2: =SUM(AC2:AK2) -> 201
A3: R | B3: Registered | D3: 1001 | E3: 1053 | F3: 15 | G3: 22 | H3: 14 | I3: 37 | J3: 76 | K3: 22 | L3: 14 | M3: 11 | N3: 23 | O3: =SUM(F3:N3) -> 234 | Q3: ='X,Y restore'!G3 -> 15 | R3: ='X,Y restore'!H3 -> 13 | S3: ='X,Y restore'!I3 -> 14 | T3: ='X,Y restore'!AI3 -> 8 | U3: ='X,Y restore'!AG3 -> 6 | V3: ='X,Y restore'!AJ3 -> 6 | W3: ='X,Y restore'!M3 -> 14 | X3: ='X,Y restore'!N3 -> 11 | Y3: ='X,Y restore'!O3 -> 8 | Z3: =SUM(Q3:Y3) -> 95 | AA3: =O3/Z3 -> 2.4631579 | AC3: =ROUND($AA3*Q3,0) -> 37 | AD3: =ROUND($AA3*R3,0) -> 32 | AE3: =ROUND($AA3*S3,0) -> 34 | AF3: =ROUND($AA3*T3,0) -> 20 | AG3: =ROUND($AA3*U3,0) -> 15 | AH3: =ROUND($AA3*V3,0) -> 15 | AI3: =ROUND($AA3*W3,0) -> 34 | AJ3: =ROUND($AA3*X3,0) -> 27 | AK3: =ROUND($AA3*Y3,0) -> 20 | AL3: =SUM(AC3:AK3) -> 234
A4: A1 | B4: Hyt Early | D4: 1004 | E4: 1917 | F4: 7 | G4: 17 | H4: 9 | I4: 21 | J4: 72 | K4: 24 | L4: 6 | M4: 11 | N4: 63 | O4: =SUM(F4:N4) -> 230 | Q4: ='X,Y restore'!G4 -> 7 | R4: ='X,Y restore'!H4 -> 8 | S4: ='X,Y restore'!I4 -> 9 | T4: ='X,Y restore'!AI4 -> 5 | U4: ='X,Y restore'!AG4 -> 6 | V4: ='X,Y restore'!AJ4 -> 9 | W4: ='X,Y restore'!M4 -> 7 | X4: ='X,Y restore'!N4 -> 11 | Y4: ='X,Y restore'!O4 -> 22 | Z4: =SUM(Q4:Y4) -> 84 | AA4: =O4/Z4 -> 2.7380952 | AC4: =ROUND($AA4*Q4,0) -> 19 | AD4: =ROUND($AA4*R4,0) -> 22 | AE4: =ROUND($AA4*S4,0) -> 25 | AF4: =ROUND($AA4*T4,0) -> 14 | AG4: =ROUND($AA4*U4,0) -> 16 | AH4: =ROUND($AA4*V4,0) -> 25 | AI4: =ROUND($AA4*W4,0) -> 19 | AJ4: =ROUND($AA4*X4,0) -> 30 | AK4: =ROUND($AA4*Y4,0) -> 60 | AL4: =SUM(AC4:AK4) -> 230
A5: A2 | B5: Hyt Mail | D5: 1005 | E5: 1599 | F5: 14 | G5: 26 | H5: 11 | I5: 65 | J5: 130 | K5: 29 | L5: 27 | M5: 10 | N5: 62 | O5: =SUM(F5:N5) -> 374 | Q5: ='X,Y restore'!G5 -> 14 | R5: ='X,Y restore'!H5 -> 7 | S5: ='X,Y restore'!I5 -> 11 | T5: ='X,Y restore'!AI5 -> 17 | U5: ='X,Y restore'!AG5 -> 6 | V5: ='X,Y restore'!AJ5 -> 8 | W5: ='X,Y restore'!M5 -> 25 | X5: ='X,Y restore'!N5 -> 10 | Y5: ='X,Y restore'!O5 -> 18 | Z5: =SUM(Q5:Y5) -> 116 | AA5: =O5/Z5 -> 3.2241379 | AC5: =ROUND($AA5*Q5,0) -> 45 | AD5: =ROUND($AA5*R5,0) -> 23 | AE5: =ROUND($AA5*S5,0) -> 35 | AF5: =ROUND($AA5*T5,0) -> 55 | AG5: =ROUND($AA5*U5,0) -> 19 | AH5: =ROUND($AA5*V5,0) -> 26 | AI5: =ROUND($AA5*W5,0) -> 81 | AJ5: =ROUND($AA5*X5,0) -> 32 | AK5: =ROUND($AA5*Y5,0) -> 58 | AL5: =SUM(AC5:AK5) -> 374
A6: A3 | B6: Hyt EDV | D6: 1006 | E6: 1548 | F6: 5 | G6: 27 | H6: 6 | I6: 33 | J6: 68 | K6: 27 | L6: 16 | M6: 6 | N6: 39 | O6: =SUM(F6:N6) -> 227 | Q6: ='X,Y restore'!G6 -> 5 | R6: ='X,Y restore'!H6 -> 5 | S6: ='X,Y restore'!I6 -> 6 | T6: ='X,Y restore'!AI6 -> 8 | U6: ='X,Y restore'!AG6 -> 4 | V6: ='X,Y restore'!AJ6 -> 9 | W6: ='X,Y restore'!M6 -> 15 | X6: ='X,Y restore'!N6 -> 6 | Y6: ='X,Y restore'!O6 -> 16 | Z6: =SUM(Q6:Y6) -> 74 | AA6: =O6/Z6 -> 3.0675676 | AC6: =ROUND($AA6*Q6,0) -> 15 | AD6: =ROUND($AA6*R6,0) -> 15 | AE6: =ROUND($AA6*S6,0) -> 18 | AF6: =ROUND($AA6*T6,0) -> 25 | AG6: =ROUND($AA6*U6,0) -> 12 | AH6: =ROUND($AA6*V6,0) -> 28 | AI6: =ROUND($AA6*W6,0) -> 46 | AJ6: =ROUND($AA6*X6,0) -> 18 | AK6: =ROUND($AA6*Y6,0) -> 49 | AL6: =SUM(AC6:AK6) -> 226
A7: B1 | B7: McMahill Early | D7: 1007 | E7: 2681 | F7: 14 | G7: 24 | H7: 9 | I7: 36 | J7: 102 | K7: 33 | L7: 17 | M7: 15 | N7: 47 | O7: =SUM(F7:N7) -> 297 | Q7: ='X,Y restore'!G7 -> 14 | R7: ='X,Y restore'!H7 -> 15 | S7: ='X,Y restore'!I7 -> 9 | T7: ='X,Y restore'!AI7 -> 9 | U7: ='X,Y restore'!AG7 -> 8 | V7: ='X,Y restore'!AJ7 -> 8 | W7: ='X,Y restore'!M7 -> 17 | X7: ='X,Y restore'!N7 -> 15 | Y7: ='X,Y restore'!O7 -> 12 | Z7: =SUM(Q7:Y7) -> 107 | AA7: =O7/Z7 -> 2.7757009 | AC7: =ROUND($AA7*Q7,0) -> 39 | AD7: =ROUND($AA7*R7,0) -> 42 | AE7: =ROUND($AA7*S7,0) -> 25 | AF7: =ROUND($AA7*T7,0) -> 25 | AG7: =ROUND($AA7*U7,0) -> 22 | AH7: =ROUND($AA7*V7,0) -> 22 | AI7: =ROUND($AA7*W7,0) -> 47 | AJ7: =ROUND($AA7*X7,0) -> 42 | AK7: =ROUND($AA7*Y7,0) -> 33 | AL7: =SUM(AC7:AK7) -> 297
A8: B2 | B8: McMahill Mail | D8: 1008 | E8: 3439 | F8: 15 | G8: 38 | H8: 25 | I8: 65 | J8: 139 | K8: 35 | L8: 27 | M8: 16 | N8: 64 | O8: =SUM(F8:N8) -> 424 | Q8: ='X,Y restore'!G8 -> 15 | R8: ='X,Y restore'!H8 -> 11 | S8: ='X,Y restore'!I8 -> 25 | T8: ='X,Y restore'!AI8 -> 16 | U8: ='X,Y restore'!AG8 -> 9 | V8: ='X,Y restore'!AJ8 -> 16 | W8: ='X,Y restore'!M8 -> 26 | X8: ='X,Y restore'!N8 -> 16 | Y8: ='X,Y restore'!O8 -> 38 | Z8: =SUM(Q8:Y8) -> 172 | AA8: =O8/Z8 -> 2.4651163 | AC8: =ROUND($AA8*Q8,0) -> 37 | AD8: =ROUND($AA8*R8,0) -> 27 | AE8: =ROUND($AA8*S8,0) -> 62 | AF8: =ROUND($AA8*T8,0) -> 39 | AG8: =ROUND($AA8*U8,0) -> 22 | AH8: =ROUND($AA8*V8,0) -> 39 | AI8: =ROUND($AA8*W8,0) -> 64 | AJ8: =ROUND($AA8*X8,0) -> 39 | AK8: =ROUND($AA8*Y8,0) -> 94 | AL8: =SUM(AC8:AK8) -> 423
A9: B3 | B9: McMahill EDV | D9: 1009 | E9: 1380 | F9: 23 | G9: 25 | H9: 29 | I9: 67 | J9: 118 | K9: 46 | L9: 24 | M9: 21 | N9: 51 | O9: =SUM(F9:N9) -> 404 | Q9: ='X,Y restore'!G9 -> 23 | R9: ='X,Y restore'!H9 -> 15 | S9: ='X,Y restore'!I9 -> 29 | T9: ='X,Y restore'!AI9 -> 13 | U9: ='X,Y restore'!AG9 -> 11 | V9: ='X,Y restore'!AJ9 -> 15 | W9: ='X,Y restore'!M9 -> 23 | X9: ='X,Y restore'!N9 -> 21 | Y9: ='X,Y restore'!O9 -> 23 | Z9: =SUM(Q9:Y9) -> 173 | AA9: =O9/Z9 -> 2.3352601 | AC9: =ROUND($AA9*Q9,0) -> 54 | AD9: =ROUND($AA9*R9,0) -> 35 | AE9: =ROUND($AA9*S9,0) -> 68 | AF9: =ROUND($AA9*T9,0) -> 30 | AG9: =ROUND($AA9*U9,0) -> 26 | AH9: =ROUND($AA9*V9,0) -> 35 | AI9: =ROUND($AA9*W9,0) -> 54 | AJ9: =ROUND($AA9*X9,0) -> 49 | AK9: =ROUND($AA9*Y9,0) -> 54 | AL9: =SUM(AC9:AK9) -> 405
A10: C1 | B10: Roberts Early | D10: 1012 | E10: 1883 | F10: 23 | G10: 57 | H10: 28 | I10: 82 | J10: 244 | K10: 69 | L10: 35 | M10: 22 | N10: 121 | O10: =SUM(F10:N10) -> 681 | Q10: ='X,Y restore'!G10 -> 23 | R10: ='X,Y restore'!H10 -> 18 | S10: ='X,Y restore'!I10 -> 28 | T10: ='X,Y restore'!AI10 -> 19 | U10: ='X,Y restore'!AG10 -> 14 | V10: ='X,Y restore'!AJ10 -> 26 | W10: ='X,Y restore'!M10 -> 34 | X10: ='X,Y restore'!N10 -> 22 | Y10: ='X,Y restore'!O10 -> 52 | Z10: =SUM(Q10:Y10) -> 236 | AA10: =O10/Z10 -> 2.8855932 | AC10: =ROUND($AA10*Q10,0) -> 66 | AD10: =ROUND($AA10*R10,0) -> 52 | AE10: =ROUND($AA10*S10,0) -> 81 | AF10: =ROUND($AA10*T10,0) -> 55 | AG10: =ROUND($AA10*U10,0) -> 40 | AH10: =ROUND($AA10*V10,0) -> 75 | AI10: =ROUND($AA10*W10,0) -> 98 | AJ10: =ROUND($AA10*X10,0) -> 63 | AK10: =ROUND($AA10*Y10,0) -> 150 | AL10: =SUM(AC10:AK10) -> 680
A11: C2 | B11: Roberts Mail | D11: 1015 | E11: 2510 | F11: 34 | G11: 48 | H11: 19 | I11: 69 | J11: 155 | K11: 42 | L11: 14 | M11: 20 | N11: 78 | O11: =SUM(F11:N11) -> 479 | Q11: ='X,Y restore'!G11 -> 34 | R11: ='X,Y restore'!H11 -> 36 | S11: ='X,Y restore'!I11 -> 19 | T11: ='X,Y restore'!AI11 -> 15 | U11: ='X,Y restore'!AG11 -> 12 | V11: ='X,Y restore'!AJ11 -> 8 | W11: ='X,Y restore'!M11 -> 16 | X11: ='X,Y restore'!N11 -> 20 | Y11: ='X,Y restore'!O11 -> 17 | Z11: =SUM(Q11:Y11) -> 177 | AA11: =O11/Z11 -> 2.7062147 | AC11: =ROUND($AA11*Q11,0) -> 92 | AD11: =ROUND($AA11*R11,0) -> 97 | AE11: =ROUND($AA11*S11,0) -> 51 | AF11: =ROUND($AA11*T11,0) -> 41 | AG11: =ROUND($AA11*U11,0) -> 32 | AH11: =ROUND($AA11*V11,0) -> 22 | AI11: =ROUND($AA11*W11,0) -> 43 | AJ11: =ROUND($AA11*X11,0) -> 54 | AK11: =ROUND($AA11*Y11,0) -> 46 | AL11: =SUM(AC11:AK11) -> 478
A12: C3 | B12: Roberts EDV | D12: 1016 | E12: 485 | F12: 4 | G12: 15 | H12: 12 | I12: 21 | J12: 47 | K12: 17 | L12: 7 | M12: 2 | N12: 28 | O12: =SUM(F12:N12) -> 153 | Q12: ='X,Y restore'!G12 -> 4 | R12: ='X,Y restore'!H12 -> 1 | S12: ='X,Y restore'!I12 -> 12 | T12: ='X,Y restore'!AI12 -> 4 | U12: ='X,Y restore'!AG12 -> 1 | V12: ='X,Y restore'!AJ12 -> 11 | W12: ='X,Y restore'!M12 -> 7 | X12: ='X,Y restore'!N12 -> 2 | Y12: ='X,Y restore'!O12 -> 29 | Z12: =SUM(Q12:Y12) -> 71 | AA12: =O12/Z12 -> 2.1549296 | AC12: =ROUND($AA12*Q12,0) -> 9 | AD12: =ROUND($AA12*R12,0) -> 2 | AE12: =ROUND($AA12*S12,0) -> 26 | AF12: =ROUND($AA12*T12,0) -> 9 | AG12: =ROUND($AA12*U12,0) -> 2 | AH12: =ROUND($AA12*V12,0) -> 24 | AI12: =ROUND($AA12*W12,0) -> 15 | AJ12: =ROUND($AA12*X12,0) -> 4 | AK12: =ROUND($AA12*Y12,0) -> 62 | AL12: =SUM(AC12:AK12) -> 153
D13: 1038 | E13: 2098 | F13: 14 | G13: 38 | H13: 10 | I13: 59 | J13: 120 | K13: 27 | L13: 13 | M13: 9 | N13: 49 | O13: =SUM(F13:N13) -> 339 | Q13: ='X,Y restore'!G13 -> 14 | R13: ='X,Y restore'!H13 -> 15 | S13: ='X,Y restore'!I13 -> 10 | T13: ='X,Y restore'!AI13 -> 13 | U13: ='X,Y restore'!AG13 -> 6 | V13: ='X,Y restore'!AJ13 -> 6 | W13: ='X,Y restore'!M13 -> 14 | X13: ='X,Y restore'!N13 -> 9 | Y13: ='X,Y restore'!O13 -> 14 | Z13: =SUM(Q13:Y13) -> 101 | AA13: =O13/Z13 -> 3.3564356 | AC13: =ROUND($AA13*Q13,0) -> 47 | AD13: =ROUND($AA13*R13,0) -> 50 | AE13: =ROUND($AA13*S13,0) -> 34 | AF13: =ROUND($AA13*T13,0) -> 44 | AG13: =ROUND($AA13*U13,0) -> 20 | AH13: =ROUND($AA13*V13,0) -> 20 | AI13: =ROUND($AA13*W13,0) -> 47 | AJ13: =ROUND($AA13*X13,0) -> 30 | AK13: =ROUND($AA13*Y13,0) -> 47 | AL13: =SUM(AC13:AK13) -> 339
D14: 1039 | E14: 3242 | F14: 27 | G14: 74 | H14: 33 | I14: 143 | J14: 271 | K14: 73 | L14: 38 | M14: 22 | N14: 116 | O14: =SUM(F14:N14) -> 797 | Q14: ='X,Y restore'!G14 -> 27 | R14: ='X,Y restore'!H14 -> 22 | S14: ='X,Y restore'!I14 -> 33 | T14: ='X,Y restore'!AI14 -> 30 | U14: ='X,Y restore'!AG14 -> 14 | V14: ='X,Y restore'!AJ14 -> 24 | W14: ='X,Y restore'!M14 -> 38 | X14: ='X,Y restore'!N14 -> 22 | Y14: ='X,Y restore'!O14 -> 51 | Z14: =SUM(Q14:Y14) -> 261 | AA14: =O14/Z14 -> 3.0536398 | AC14: =ROUND($AA14*Q14,0) -> 82 | AD14: =ROUND($AA14*R14,0) -> 67 | AE14: =ROUND($AA14*S14,0) -> 101 | AF14: =ROUND($AA14*T14,0) -> 92 | AG14: =ROUND($AA14*U14,0) -> 43 | AH14: =ROUND($AA14*V14,0) -> 73 | AI14: =ROUND($AA14*W14,0) -> 116 | AJ14: =ROUND($AA14*X14,0) -> 67 | AK14: =ROUND($AA14*Y14,0) -> 156 | AL14: =SUM(AC14:AK14) -> 797
D15: 1063 | E15: 1412 | F15: 12 | G15: 27 | H15: 24 | I15: 49 | J15: 115 | K15: 48 | L15: 21 | M15: 7 | N15: 46 | O15: =SUM(F15:N15) -> 349 | Q15: ='X,Y restore'!G15 -> 12 | R15: ='X,Y restore'!H15 -> 3 | S15: ='X,Y restore'!I15 -> 24 | T15: ='X,Y restore'!AI15 -> 9 | U15: ='X,Y restore'!AG15 -> 5 | V15: ='X,Y restore'!AJ15 -> 19 | W15: ='X,Y restore'!M15 -> 20 | X15: ='X,Y restore'!N15 -> 7 | Y15: ='X,Y restore'!O15 -> 31 | Z15: =SUM(Q15:Y15) -> 130 | AA15: =O15/Z15 -> 2.6846154 | AC15: =ROUND($AA15*Q15,0) -> 32 | AD15: =ROUND($AA15*R15,0) -> 8 | AE15: =ROUND($AA15*S15,0) -> 64 | AF15: =ROUND($AA15*T15,0) -> 24 | AG15: =ROUND($AA15*U15,0) -> 13 | AH15: =ROUND($AA15*V15,0) -> 51 | AI15: =ROUND($AA15*W15,0) -> 54 | AJ15: =ROUND($AA15*X15,0) -> 19 | AK15: =ROUND($AA15*Y15,0) -> 83 | AL15: =SUM(AC15:AK15) -> 348
A16: Results | B16: Original Totals | C16: Restored Totals | D16: 1074 | E16: 2203 | F16: 6 | G16: 47 | H16: 20 | I16: 37 | J16: 230 | K16: 77 | L16: 11 | M16: 19 | N16: 84 | O16: =SUM(F16:N16) -> 531 | Q16: ='X,Y restore'!G16 -> 6 | R16: ='X,Y restore'!H16 -> 8 | S16: ='X,Y restore'!I16 -> 20 | T16: ='X,Y restore'!AI16 -> 3 | U16: ='X,Y restore'!AG16 -> 12 | V16: ='X,Y restore'!AJ16 -> 44 | W16: ='X,Y restore'!M16 -> 14 | X16: ='X,Y restore'!N16 -> 19 | Y16: ='X,Y restore'!O16 -> 115 | Z16: =SUM(Q16:Y16) -> 241 | AA16: =O16/Z16 -> 2.2033195 | AC16: =ROUND($AA16*Q16,0) -> 13 | AD16: =ROUND($AA16*R16,0) -> 18 | AE16: =ROUND($AA16*S16,0) -> 44 | AF16: =ROUND($AA16*T16,0) -> 7 | AG16: =ROUND($AA16*U16,0) -> 26 | AH16: =ROUND($AA16*V16,0) -> 97 | AI16: =ROUND($AA16*W16,0) -> 31 | AJ16: =ROUND($AA16*X16,0) -> 42 | AK16: =ROUND($AA16*Y16,0) -> 253 | AL16: =SUM(AC16:AK16) -> 531
A17: A1 | B17: 11627 | C17: 30715 | D17: 1302 | E17: 3655 | F17: 32 | G17: 42 | H17: 14 | I17: 85 | J17: 232 | K17: 60 | L17: 31 | M17: 38 | N17: 81 | O17: =SUM(F17:N17) -> 615 | Q17: ='X,Y restore'!G17 -> 32 | R17: ='X,Y restore'!H17 -> 43 | S17: ='X,Y restore'!I17 -> 14 | T17: ='X,Y restore'!AI17 -> 20 | U17: ='X,Y restore'!AG17 -> 21 | V17: ='X,Y restore'!AJ17 -> 10 | W17: ='X,Y restore'!M17 -> 31 | X17: ='X,Y restore'!N17 -> 38 | Y17: ='X,Y restore'!O17 -> 14 | Z17: =SUM(Q17:Y17) -> 223 | AA17: =O17/Z17 -> 2.7578475 | AC17: =ROUND($AA17*Q17,0) -> 88 | AD17: =ROUND($AA17*R17,0) -> 119 | AE17: =ROUND($AA17*S17,0) -> 39 | AF17: =ROUND($AA17*T17,0) -> 55 | AG17: =ROUND($AA17*U17,0) -> 58 | AH17: =ROUND($AA17*V17,0) -> 28 | AI17: =ROUND($AA17*W17,0) -> 85 | AJ17: =ROUND($AA17*X17,0) -> 105 | AK17: =ROUND($AA17*Y17,0) -> 39 | AL17: =SUM(AC17:AK17) -> 616
A18: A2 | B18: 20748 | C18: 25064 | D18: 1304 | E18: 2660 | F18: 19 | G18: 40 | H18: 30 | I18: 53 | J18: 145 | K18: 35 | L18: 28 | M18: 13 | N18: 64 | O18: =SUM(F18:N18) -> 427 | Q18: ='X,Y restore'!G18 -> 19 | R18: ='X,Y restore'!H18 -> 8 | S18: ='X,Y restore'!I18 -> 30 | T18: ='X,Y restore'!AI18 -> 13 | U18: ='X,Y restore'!AG18 -> 8 | V18: ='X,Y restore'!AJ18 -> 17 | W18: ='X,Y restore'!M18 -> 27 | X18: ='X,Y restore'!N18 -> 13 | Y18: ='X,Y restore'!O18 -> 36 | Z18: =SUM(Q18:Y18) -> 171 | AA18: =O18/Z18 -> 2.497076 | AC18: =ROUND($AA18*Q18,0) -> 47 | AD18: =ROUND($AA18*R18,0) -> 20 | AE18: =ROUND($AA18*S18,0) -> 75 | AF18: =ROUND($AA18*T18,0) -> 32 | AG18: =ROUND($AA18*U18,0) -> 20 | AH18: =ROUND($AA18*V18,0) -> 42 | AI18: =ROUND($AA18*W18,0) -> 67 | AJ18: =ROUND($AA18*X18,0) -> 32 | AK18: =ROUND($AA18*Y18,0) -> 90 | AL18: =SUM(AC18:AK18) -> 425
A19: A3 | B19: 13275 | C19: 33776 | D19: 1307 | E19: 2027 | F19: 29 | G19: 30 | H19: 27 | I19: 66 | J19: 142 | K19: 44 | L19: 18 | M19: 18 | N19: 63 | O19: =SUM(F19:N19) -> 437 | Q19: ='X,Y restore'!G19 -> 29 | R19: ='X,Y restore'!H19 -> 16 | S19: ='X,Y restore'!I19 -> 27 | T19: ='X,Y restore'!AI19 -> 14 | U19: ='X,Y restore'!AG19 -> 10 | V19: ='X,Y restore'!AJ19 -> 12 | W19: ='X,Y restore'!M19 -> 19 | X19: ='X,Y restore'!N19 -> 18 | Y19: ='X,Y restore'!O19 -> 23 | Z19: =SUM(Q19:Y19) -> 168 | AA19: =O19/Z19 -> 2.6011905 | AC19: =ROUND($AA19*Q19,0) -> 75 | AD19: =ROUND($AA19*R19,0) -> 42 | AE19: =ROUND($AA19*S19,0) -> 70 | AF19: =ROUND($AA19*T19,0) -> 36 | AG19: =ROUND($AA19*U19,0) -> 26 | AH19: =ROUND($AA19*V19,0) -> 31 | AI19: =ROUND($AA19*W19,0) -> 49 | AJ19: =ROUND($AA19*X19,0) -> 47 | AK19: =ROUND($AA19*Y19,0) -> 60 | AL19: =SUM(AC19:AK19) -> 436
A20: B1 | B20: 37509 | C20: 20701 | D20: 1318 | E20: 1739 | F20: 14 | G20: 20 | H20: 12 | I20: 29 | J20: 71 | K20: 29 | L20: 5 | M20: 6 | N20: 28 | O20: =SUM(F20:N20) -> 214 | Q20: ='X,Y restore'!G20 -> 14 | R20: ='X,Y restore'!H20 -> 10 | S20: ='X,Y restore'!I20 -> 12 | T20: ='X,Y restore'!AI20 -> 5 | U20: ='X,Y restore'!AG20 -> 4 | V20: ='X,Y restore'!AJ20 -> 6 | W20: ='X,Y restore'!M20 -> 6 | X20: ='X,Y restore'!N20 -> 6 | Y20: ='X,Y restore'!O20 -> 9 | Z20: =SUM(Q20:Y20) -> 72 | AA20: =O20/Z20 -> 2.9722222 | AC20: =ROUND($AA20*Q20,0) -> 42 | AD20: =ROUND($AA20*R20,0) -> 30 | AE20: =ROUND($AA20*S20,0) -> 36 | AF20: =ROUND($AA20*T20,0) -> 15 | AG20: =ROUND($AA20*U20,0) -> 12 | AH20: =ROUND($AA20*V20,0) -> 18 | AI20: =ROUND($AA20*W20,0) -> 18 | AJ20: =ROUND($AA20*X20,0) -> 18 | AK20: =ROUND($AA20*Y20,0) -> 27 | AL20: =SUM(AC20:AK20) -> 216
A21: B2 | B21: 82460 | C21: 15887 | D21: 1327 | E21: 2196 | F21: 19 | G21: 22 | H21: 15 | I21: 33 | J21: 85 | K21: 23 | L21: 18 | M21: 13 | N21: 36 | O21: =SUM(F21:N21) -> 264 | Q21: ='X,Y restore'!G21 -> 19 | R21: ='X,Y restore'!H21 -> 13 | S21: ='X,Y restore'!I21 -> 15 | T21: ='X,Y restore'!AI21 -> 8 | U21: ='X,Y restore'!AG21 -> 7 | V21: ='X,Y restore'!AJ21 -> 7 | W21: ='X,Y restore'!M21 -> 17 | X21: ='X,Y restore'!N21 -> 13 | Y21: ='X,Y restore'!O21 -> 10 | Z21: =SUM(Q21:Y21) -> 109 | AA21: =O21/Z21 -> 2.4220183 | AC21: =ROUND($AA21*Q21,0) -> 46 | AD21: =ROUND($AA21*R21,0) -> 31 | AE21: =ROUND($AA21*S21,0) -> 36 | AF21: =ROUND($AA21*T21,0) -> 19 | AG21: =ROUND($AA21*U21,0) -> 17 | AH21: =ROUND($AA21*V21,0) -> 17 | AI21: =ROUND($AA21*W21,0) -> 41 | AJ21: =ROUND($AA21*X21,0) -> 31 | AK21: =ROUND($AA21*Y21,0) -> 24 | AL21: =SUM(AC21:AK21) -> 262
A22: B3 | B22: 28967 | C22: 23933 | D22: 1328 | E22: 1757 | F22: 11 | G22: 22 | H22: 13 | I22: 38 | J22: 105 | K22: 25 | L22: 20 | M22: 8 | N22: 45 | O22: =SUM(F22:N22) -> 287 | Q22: ='X,Y restore'!G22 -> 11 | R22: ='X,Y restore'!H22 -> 5 | S22: ='X,Y restore'!I22 -> 13 | T22: ='X,Y restore'!AI22 -> 10 | U22: ='X,Y restore'!AG22 -> 5 | V22: ='X,Y restore'!AJ22 -> 9 | W22: ='X,Y restore'!M22 -> 19 | X22: ='X,Y restore'!N22 -> 8 | Y22: ='X,Y restore'!O22 -> 19 | Z22: =SUM(Q22:Y22) -> 99 | AA22: =O22/Z22 -> 2.8989899 | AC22: =ROUND($AA22*Q22,0) -> 32 | AD22: =ROUND($AA22*R22,0) -> 14 | AE22: =ROUND($AA22*S22,0) -> 38 | AF22: =ROUND($AA22*T22,0) -> 29 | AG22: =ROUND($AA22*U22,0) -> 14 | AH22: =ROUND($AA22*V22,0) -> 26 | AI22: =ROUND($AA22*W22,0) -> 55 | AJ22: =ROUND($AA22*X22,0) -> 23 | AK22: =ROUND($AA22*Y22,0) -> 55 | AL22: =SUM(AC22:AK22) -> 286
A23: C1 | B23: 13901 | C23: 35478 | D23: 1330 | E23: 1937 | F23: 27 | G23: 41 | H23: 29 | I23: 69 | J23: 130 | K23: 66 | L23: 21 | M23: 12 | N23: 43 | O23: =SUM(F23:N23) -> 438 | Q23: ='X,Y restore'!G23 -> 27 | R23: ='X,Y restore'!H23 -> 15 | S23: ='X,Y restore'!I23 -> 29 | T23: ='X,Y restore'!AI23 -> 11 | U23: ='X,Y restore'!AG23 -> 7 | V23: ='X,Y restore'!AJ23 -> 16 | W23: ='X,Y restore'!M23 -> 21 | X23: ='X,Y restore'!N23 -> 12 | Y23: ='X,Y restore'!O23 -> 18 | Z23: =SUM(Q23:Y23) -> 156 | AA23: =O23/Z23 -> 2.8076923 | AC23: =ROUND($AA23*Q23,0) -> 76 | AD23: =ROUND($AA23*R23,0) -> 42 | AE23: =ROUND($AA23*S23,0) -> 81 | AF23: =ROUND($AA23*T23,0) -> 31 | AG23: =ROUND($AA23*U23,0) -> 20 | AH23: =ROUND($AA23*V23,0) -> 45 | AI23: =ROUND($AA23*W23,0) -> 59 | AJ23: =ROUND($AA23*X23,0) -> 34 | AK23: =ROUND($AA23*Y23,0) -> 51 | AL23: =SUM(AC23:AK23) -> 439
A24: C2 | B24: 11290 | C24: 28463 | D24: 1331 | E24: 1777 | F24: 11 | G24: 30 | H24: 24 | I24: 27 | J24: 86 | K24: 31 | L24: 11 | M24: 6 | N24: 44 | O24: =SUM(F24:N24) -> 270 | Q24: ='X,Y restore'!G24 -> 11 | R24: ='X,Y restore'!H24 -> 3 | S24: ='X,Y restore'!I24 -> 24 | T24: ='X,Y restore'!AI24 -> 5 | U24: ='X,Y restore'!AG24 -> 4 | V24: ='X,Y restore'!AJ24 -> 16 | W24: ='X,Y restore'!M24 -> 12 | X24: ='X,Y restore'!N24 -> 6 | Y24: ='X,Y restore'!O24 -> 37 | Z24: =SUM(Q24:Y24) -> 118 | AA24: =O24/Z24 -> 2.2881356 | AC24: =ROUND($AA24*Q24,0) -> 25 | AD24: =ROUND($AA24*R24,0) -> 7 | AE24: =ROUND($AA24*S24,0) -> 55 | AF24: =ROUND($AA24*T24,0) -> 11 | AG24: =ROUND($AA24*U24,0) -> 9 | AH24: =ROUND($AA24*V24,0) -> 37 | AI24: =ROUND($AA24*W24,0) -> 27 | AJ24: =ROUND($AA24*X24,0) -> 14 | AK24: =ROUND($AA24*Y24,0) -> 85 | AL24: =SUM(AC24:AK24) -> 270
A25: C3 | B25: 36953 | C25: 42733 | D25: 1333 | E25: 1478 | F25: 19 | G25: 36 | H25: 17 | I25: 50 | J25: 82 | K25: 37 | L25: 11 | M25: 19 | N25: 39 | O25: =SUM(F25:N25) -> 310 | Q25: ='X,Y restore'!G25 -> 19 | R25: ='X,Y restore'!H25 -> 32 | S25: ='X,Y restore'!I25 -> 17 | T25: ='X,Y restore'!AI25 -> 9 | U25: ='X,Y restore'!AG25 -> 9 | V25: ='X,Y restore'!AJ25 -> 9 | W25: ='X,Y restore'!M25 -> 12 | X25: ='X,Y restore'!N25 -> 19 | Y25: ='X,Y restore'!O25 -> 14 | Z25: =SUM(Q25:Y25) -> 140 | AA25: =O25/Z25 -> 2.2142857 | AC25: =ROUND($AA25*Q25,0) -> 42 | AD25: =ROUND($AA25*R25,0) -> 71 | AE25: =ROUND($AA25*S25,0) -> 38 | AF25: =ROUND($AA25*T25,0) -> 20 | AG25: =ROUND($AA25*U25,0) -> 20 | AH25: =ROUND($AA25*V25,0) -> 20 | AI25: =ROUND($AA25*W25,0) -> 27 | AJ25: =ROUND($AA25*X25,0) -> 42 | AK25: =ROUND($AA25*Y25,0) -> 31 | AL25: =SUM(AC25:AK25) -> 311
D26: 1334 | E26: 1815 | F26: 17 | G26: 31 | H26: 18 | I26: 52 | J26: 117 | K26: 29 | L26: 14 | M26: 11 | N26: 39 | O26: =SUM(F26:N26) -> 328 | Q26: ='X,Y restore'!G26 -> 17 | R26: ='X,Y restore'!H26 -> 13 | S26: ='X,Y restore'!I26 -> 18 | T26: ='X,Y restore'!AI26 -> 11 | U26: ='X,Y restore'!AG26 -> 7 | V26: ='X,Y restore'!AJ26 -> 9 | W26: ='X,Y restore'!M26 -> 15 | X26: ='X,Y restore'!N26 -> 11 | Y26: ='X,Y restore'!O26 -> 17 | Z26: =SUM(Q26:Y26) -> 118 | AA26: =O26/Z26 -> 2.779661 | AC26: =ROUND($AA26*Q26,0) -> 47 | AD26: =ROUND($AA26*R26,0) -> 36 | AE26: =ROUND($AA26*S26,0) -> 50 | AF26: =ROUND($AA26*T26,0) -> 31 | AG26: =ROUND($AA26*U26,0) -> 19 | AH26: =ROUND($AA26*V26,0) -> 25 | AI26: =ROUND($AA26*W26,0) -> 42 | AJ26: =ROUND($AA26*X26,0) -> 31 | AK26: =ROUND($AA26*Y26,0) -> 47 | AL26: =SUM(AC26:AK26) -> 328
A27: Candidates | B27: Original | C27: Restored | D27: 1335 | E27: 1591 | F27: 11 | G27: 30 | H27: 27 | I27: 57 | J27: 121 | K27: 34 | L27: 12 | M27: 16 | N27: 59 | O27: =SUM(F27:N27) -> 367 | Q27: ='X,Y restore'!G27 -> 11 | R27: ='X,Y restore'!H27 -> 8 | S27: ='X,Y restore'!I27 -> 27 | T27: ='X,Y restore'!AI27 -> 12 | U27: ='X,Y restore'!AG27 -> 9 | V27: ='X,Y restore'!AJ27 -> 18 | W27: ='X,Y restore'!M27 -> 13 | X27: ='X,Y restore'!N27 -> 16 | Y27: ='X,Y restore'!O27 -> 50 | Z27: =SUM(Q27:Y27) -> 164 | AA27: =O27/Z27 -> 2.2378049 | AC27: =ROUND($AA27*Q27,0) -> 25 | AD27: =ROUND($AA27*R27,0) -> 18 | AE27: =ROUND($AA27*S27,0) -> 60 | AF27: =ROUND($AA27*T27,0) -> 27 | AG27: =ROUND($AA27*U27,0) -> 20 | AH27: =ROUND($AA27*V27,0) -> 40 | AI27: =ROUND($AA27*W27,0) -> 29 | AJ27: =ROUND($AA27*X27,0) -> 36 | AK27: =ROUND($AA27*Y27,0) -> 112 | AL27: =SUM(AC27:AK27) -> 367
A28: Hyt | B28: =B17+B18+B19 -> 45650 | C28: =C17+C18+C19 -> 89555 | D28: 1336 | E28: 1443 | F28: 17 | G28: 34 | H28: 7 | I28: 26 | J28: 80 | K28: 10 | L28: 7 | M28: 10 | N28: 44 | O28: =SUM(F28:N28) -> 235 | Q28: ='X,Y restore'!G28 -> 17 | R28: ='X,Y restore'!H28 -> 27 | S28: ='X,Y restore'!I28 -> 7 | T28: ='X,Y restore'!AI28 -> 7 | U28: ='X,Y restore'!AG28 -> 6 | V28: ='X,Y restore'!AJ28 -> 2 | W28: ='X,Y restore'!M28 -> 8 | X28: ='X,Y restore'!N28 -> 10 | Y28: ='X,Y restore'!O28 -> 7 | Z28: =SUM(Q28:Y28) -> 91 | AA28: =O28/Z28 -> 2.5824176 | AC28: =ROUND($AA28*Q28,0) -> 44 | AD28: =ROUND($AA28*R28,0) -> 70 | AE28: =ROUND($AA28*S28,0) -> 18 | AF28: =ROUND($AA28*T28,0) -> 18 | AG28: =ROUND($AA28*U28,0) -> 15 | AH28: =ROUND($AA28*V28,0) -> 5 | AI28: =ROUND($AA28*W28,0) -> 21 | AJ28: =ROUND($AA28*X28,0) -> 26 | AK28: =ROUND($AA28*Y28,0) -> 18 | AL28: =SUM(AC28:AK28) -> 235
A29: McMahill | B29: =B20+B21+B22 -> 148936 | C29: =C20+C21+C22 -> 60521 | D29: 1341 | E29: 2852 | F29: 24 | G29: 37 | H29: 28 | I29: 66 | J29: 177 | K29: 60 | L29: 17 | M29: 12 | N29: 70 | O29: =SUM(F29:N29) -> 491 | Q29: ='X,Y restore'!G29 -> 24 | R29: ='X,Y restore'!H29 -> 9 | S29: ='X,Y restore'!I29 -> 28 | T29: ='X,Y restore'!AI29 -> 13 | U29: ='X,Y restore'!AG29 -> 8 | V29: ='X,Y restore'!AJ29 -> 18 | W29: ='X,Y restore'!M29 -> 19 | X29: ='X,Y restore'!N29 -> 12 | Y29: ='X,Y restore'!O29 -> 32 | Z29: =SUM(Q29:Y29) -> 163 | AA29: =O29/Z29 -> 3.0122699 | AC29: =ROUND($AA29*Q29,0) -> 72 | AD29: =ROUND($AA29*R29,0) -> 27 | AE29: =ROUND($AA29*S29,0) -> 84 | AF29: =ROUND($AA29*T29,0) -> 39 | AG29: =ROUND($AA29*U29,0) -> 24 | AH29: =ROUND($AA29*V29,0) -> 54 | AI29: =ROUND($AA29*W29,0) -> 57 | AJ29: =ROUND($AA29*X29,0) -> 36 | AK29: =ROUND($AA29*Y29,0) -> 96 | AL29: =SUM(AC29:AK29) -> 489
A30: Roberts | B30: =B23+B24+B25 -> 62144 | C30: =C23+C24+C25 -> 106674 | D30: 1343 | E30: 1018 | F30: 11 | G30: 19 | H30: 8 | I30: 30 | J30: 50 | K30: 21 | L30: 14 | M30: 9 | N30: 38 | O30: =SUM(F30:N30) -> 200 | Q30: ='X,Y restore'!G30 -> 11 | R30: ='X,Y restore'!H30 -> 9 | S30: ='X,Y restore'!I30 -> 8 | T30: ='X,Y restore'!AI30 -> 7 | U30: ='X,Y restore'!AG30 -> 5 | V30: ='X,Y restore'!AJ30 -> 6 | W30: ='X,Y restore'!M30 -> 13 | X30: ='X,Y restore'!N30 -> 9 | Y30: ='X,Y restore'!O30 -> 10 | Z30: =SUM(Q30:Y30) -> 78 | AA30: =O30/Z30 -> 2.5641026 | AC30: =ROUND($AA30*Q30,0) -> 28 | AD30: =ROUND($AA30*R30,0) -> 23 | AE30: =ROUND($AA30*S30,0) -> 21 | AF30: =ROUND($AA30*T30,0) -> 18 | AG30: =ROUND($AA30*U30,0) -> 13 | AH30: =ROUND($AA30*V30,0) -> 15 | AI30: =ROUND($AA30*W30,0) -> 33 | AJ30: =ROUND($AA30*X30,0) -> 23 | AK30: =ROUND($AA30*Y30,0) -> 26 | AL30: =SUM(AC30:AK30) -> 200
D31: 1344 | E31: 1496 | F31: 22 | G31: 29 | H31: 13 | I31: 49 | J31: 74 | K31: 30 | L31: 8 | M31: 6 | N31: 38 | O31: =SUM(F31:N31) -> 269 | Q31: ='X,Y restore'!G31 -> 22 | R31: ='X,Y restore'!H31 -> 11 | S31: ='X,Y restore'!I31 -> 13 | T31: ='X,Y restore'!AI31 -> 8 | U31: ='X,Y restore'!AG31 -> 4 | V31: ='X,Y restore'!AJ31 -> 5 | W31: ='X,Y restore'!M31 -> 9 | X31: ='X,Y restore'!N31 -> 6 | Y31: ='X,Y restore'!O31 -> 9 | Z31: =SUM(Q31:Y31) -> 87 | AA31: =O31/Z31 -> 3.091954 | AC31: =ROUND($AA31*Q31,0) -> 68 | AD31: =ROUND($AA31*R31,0) -> 34 | AE31: =ROUND($AA31*S31,0) -> 40 | AF31: =ROUND($AA31*T31,0) -> 25 | AG31: =ROUND($AA31*U31,0) -> 12 | AH31: =ROUND($AA31*V31,0) -> 15 | AI31: =ROUND($AA31*W31,0) -> 28 | AJ31: =ROUND($AA31*X31,0) -> 19 | AK31: =ROUND($AA31*Y31,0) -> 28 | AL31: =SUM(AC31:AK31) -> 269
A32: Mode | B32: Original | C32: Restored | D32: 1346 | E32: 2581 | F32: 34 | G32: 44 | H32: 52 | I32: 147 | J32: 231 | K32: 65 | L32: 29 | M32: 31 | N32: 96 | O32: =SUM(F32:N32) -> 729 | Q32: ='X,Y restore'!G32 -> 34 | R32: ='X,Y restore'!H32 -> 20 | S32: ='X,Y restore'!I32 -> 52 | T32: ='X,Y restore'!AI32 -> 28 | U32: ='X,Y restore'!AG32 -> 18 | V32: ='X,Y restore'!AJ32 -> 23 | W32: ='X,Y restore'!M32 -> 30 | X32: ='X,Y restore'!N32 -> 31 | Y32: ='X,Y restore'!O32 -> 53 | Z32: =SUM(Q32:Y32) -> 289 | AA32: =O32/Z32 -> 2.5224913 | AC32: =ROUND($AA32*Q32,0) -> 86 | AD32: =ROUND($AA32*R32,0) -> 50 | AE32: =ROUND($AA32*S32,0) -> 131 | AF32: =ROUND($AA32*T32,0) -> 71 | AG32: =ROUND($AA32*U32,0) -> 45 | AH32: =ROUND($AA32*V32,0) -> 58 | AI32: =ROUND($AA32*W32,0) -> 76 | AJ32: =ROUND($AA32*X32,0) -> 78 | AK32: =ROUND($AA32*Y32,0) -> 134 | AL32: =SUM(AC32:AK32) -> 729
A33: Early | B33: =B17+B20+B23 -> 63037 | C33: =C17+C20+C23 -> 86894 | D33: 1348 | E33: 1808 | F33: 11 | G33: 28 | H33: 20 | I33: 34 | J33: 76 | K33: 24 | L33: 8 | M33: 16 | N33: 41 | O33: =SUM(F33:N33) -> 258 | Q33: ='X,Y restore'!G33 -> 11 | R33: ='X,Y restore'!H33 -> 15 | S33: ='X,Y restore'!I33 -> 20 | T33: ='X,Y restore'!AI33 -> 7 | U33: ='X,Y restore'!AG33 -> 8 | V33: ='X,Y restore'!AJ33 -> 11 | W33: ='X,Y restore'!M33 -> 9 | X33: ='X,Y restore'!N33 -> 16 | Y33: ='X,Y restore'!O33 -> 27 | Z33: =SUM(Q33:Y33) -> 124 | AA33: =O33/Z33 -> 2.0806452 | AC33: =ROUND($AA33*Q33,0) -> 23 | AD33: =ROUND($AA33*R33,0) -> 31 | AE33: =ROUND($AA33*S33,0) -> 42 | AF33: =ROUND($AA33*T33,0) -> 15 | AG33: =ROUND($AA33*U33,0) -> 17 | AH33: =ROUND($AA33*V33,0) -> 23 | AI33: =ROUND($AA33*W33,0) -> 19 | AJ33: =ROUND($AA33*X33,0) -> 33 | AK33: =ROUND($AA33*Y33,0) -> 56 | AL33: =SUM(AC33:AK33) -> 259
A34: MiV | B34: =B18+B21+B24 -> 114498 | C34: =C18+C21+C24 -> 69414 | D34: 1349 | E34: 1790 | F34: 11 | G34: 17 | H34: 13 | I34: 21 | J34: 68 | K34: 29 | L34: 15 | M34: 10 | N34: 38 | O34: =SUM(F34:N34) -> 222 | Q34: ='X,Y restore'!G34 -> 11 | R34: ='X,Y restore'!H34 -> 6 | S34: ='X,Y restore'!I34 -> 13 | T34: ='X,Y restore'!AI34 -> 4 | U34: ='X,Y restore'!AG34 -> 6 | V34: ='X,Y restore'!AJ34 -> 11 | W34: ='X,Y restore'!M34 -> 14 | X34: ='X,Y restore'!N34 -> 10 | Y34: ='X,Y restore'!O34 -> 16 | Z34: =SUM(Q34:Y34) -> 91 | AA34: =O34/Z34 -> 2.4395604 | AC34: =ROUND($AA34*Q34,0) -> 27 | AD34: =ROUND($AA34*R34,0) -> 15 | AE34: =ROUND($AA34*S34,0) -> 32 | AF34: =ROUND($AA34*T34,0) -> 10 | AG34: =ROUND($AA34*U34,0) -> 15 | AH34: =ROUND($AA34*V34,0) -> 27 | AI34: =ROUND($AA34*W34,0) -> 34 | AJ34: =ROUND($AA34*X34,0) -> 24 | AK34: =ROUND($AA34*Y34,0) -> 39 | AL34: =SUM(AC34:AK34) -> 223
A35: EDV | B35: =B19+B22+B25 -> 79195 | C35: =C19+C22+C25 -> 100442 | D35: 1351 | E35: 3110 | F35: 17 | G35: 54 | H35: 20 | I35: 57 | J35: 138 | K35: 51 | L35: 25 | M35: 13 | N35: 62 | O35: =SUM(F35:N35) -> 437 | Q35: ='X,Y restore'!G35 -> 17 | R35: ='X,Y restore'!H35 -> 16 | S35: ='X,Y restore'!I35 -> 20 | T35: ='X,Y restore'!AI35 -> 13 | U35: ='X,Y restore'!AG35 -> 8 | V35: ='X,Y restore'!AJ35 -> 17 | W35: ='X,Y restore'!M35 -> 25 | X35: ='X,Y restore'!N35 -> 13 | Y35: ='X,Y restore'!O35 -> 27 | Z35: =SUM(Q35:Y35) -> 156 | AA35: =O35/Z35 -> 2.8012821 | AC35: =ROUND($AA35*Q35,0) -> 48 | AD35: =ROUND($AA35*R35,0) -> 45 | AE35: =ROUND($AA35*S35,0) -> 56 | AF35: =ROUND($AA35*T35,0) -> 36 | AG35: =ROUND($AA35*U35,0) -> 22 | AH35: =ROUND($AA35*V35,0) -> 48 | AI35: =ROUND($AA35*W35,0) -> 70 | AJ35: =ROUND($AA35*X35,0) -> 36 | AK35: =ROUND($AA35*Y35,0) -> 76 | AL35: =SUM(AC35:AK35) -> 437
D36: 1352 | E36: 1460 | F36: 9 | G36: 19 | H36: 14 | I36: 26 | J36: 65 | K36: 28 | L36: 8 | M36: 8 | N36: 46 | O36: =SUM(F36:N36) -> 223 | Q36: ='X,Y restore'!G36 -> 9 | R36: ='X,Y restore'!H36 -> 5 | S36: ='X,Y restore'!I36 -> 14 | T36: ='X,Y restore'!AI36 -> 5 | U36: ='X,Y restore'!AG36 -> 5 | V36: ='X,Y restore'!AJ36 -> 12 | W36: ='X,Y restore'!M36 -> 9 | X36: ='X,Y restore'!N36 -> 8 | Y36: ='X,Y restore'!O36 -> 26 | Z36: =SUM(Q36:Y36) -> 93 | AA36: =O36/Z36 -> 2.3978495 | AC36: =ROUND($AA36*Q36,0) -> 22 | AD36: =ROUND($AA36*R36,0) -> 12 | AE36: =ROUND($AA36*S36,0) -> 34 | AF36: =ROUND($AA36*T36,0) -> 12 | AG36: =ROUND($AA36*U36,0) -> 12 | AH36: =ROUND($AA36*V36,0) -> 29 | AI36: =ROUND($AA36*W36,0) -> 22 | AJ36: =ROUND($AA36*X36,0) -> 19 | AK36: =ROUND($AA36*Y36,0) -> 62 | AL36: =SUM(AC36:AK36) -> 224
D37: 1353 | E37: 2590 | F37: 14 | G37: 26 | H37: 14 | I37: 28 | J37: 92 | K37: 31 | L37: 19 | M37: 17 | N37: 47 | O37: =SUM(F37:N37) -> 288 | Q37: ='X,Y restore'!G37 -> 14 | R37: ='X,Y restore'!H37 -> 16 | S37: ='X,Y restore'!I37 -> 14 | T37: ='X,Y restore'!AI37 -> 7 | U37: ='X,Y restore'!AG37 -> 9 | V37: ='X,Y restore'!AJ37 -> 11 | W37: ='X,Y restore'!M37 -> 18 | X37: ='X,Y restore'!N37 -> 17 | Y37: ='X,Y restore'!O37 -> 17 | Z37: =SUM(Q37:Y37) -> 123 | AA37: =O37/Z37 -> 2.3414634 | AC37: =ROUND($AA37*Q37,0) -> 33 | AD37: =ROUND($AA37*R37,0) -> 37 | AE37: =ROUND($AA37*S37,0) -> 33 | AF37: =ROUND($AA37*T37,0) -> 16 | AG37: =ROUND($AA37*U37,0) -> 21 | AH37: =ROUND($AA37*V37,0) -> 26 | AI37: =ROUND($AA37*W37,0) -> 42 | AJ37: =ROUND($AA37*X37,0) -> 40 | AK37: =ROUND($AA37*Y37,0) -> 40 | AL37: =SUM(AC37:AK37) -> 288
D38: 1354 | E38: 3282 | F38: 18 | G38: 41 | H38: 28 | I38: 42 | J38: 136 | K38: 47 | L38: 26 | M38: 14 | N38: 89 | O38: =SUM(F38:N38) -> 441 | Q38: ='X,Y restore'!G38 -> 18 | R38: ='X,Y restore'!H38 -> 8 | S38: ='X,Y restore'!I38 -> 28 | T38: ='X,Y restore'!AI38 -> 10 | U38: ='X,Y restore'!AG38 -> 8 | V38: ='X,Y restore'!AJ38 -> 22 | W38: ='X,Y restore'!M38 -> 25 | X38: ='X,Y restore'!N38 -> 14 | Y38: ='X,Y restore'!O38 -> 47 | Z38: =SUM(Q38:Y38) -> 180 | AA38: =O38/Z38 -> 2.45 | AC38: =ROUND($AA38*Q38,0) -> 44 | AD38: =ROUND($AA38*R38,0) -> 20 | AE38: =ROUND($AA38*S38,0) -> 69 | AF38: =ROUND($AA38*T38,0) -> 25 | AG38: =ROUND($AA38*U38,0) -> 20 | AH38: =ROUND($AA38*V38,0) -> 54 | AI38: =ROUND($AA38*W38,0) -> 61 | AJ38: =ROUND($AA38*X38,0) -> 34 | AK38: =ROUND($AA38*Y38,0) -> 115 | AL38: =SUM(AC38:AK38) -> 442
D39: 1356 | E39: 2114 | F39: 12 | G39: 32 | H39: 13 | I39: 35 | J39: 103 | K39: 28 | L39: 13 | M39: 19 | N39: 42 | O39: =SUM(F39:N39) -> 297 | Q39: ='X,Y restore'!G39 -> 12 | R39: ='X,Y restore'!H39 -> 25 | S39: ='X,Y restore'!I39 -> 13 | T39: ='X,Y restore'!AI39 -> 8 | U39: ='X,Y restore'!AG39 -> 10 | V39: ='X,Y restore'!AJ39 -> 9 | W39: ='X,Y restore'!M39 -> 13 | X39: ='X,Y restore'!N39 -> 19 | Y39: ='X,Y restore'!O39 -> 17 | Z39: =SUM(Q39:Y39) -> 126 | AA39: =O39/Z39 -> 2.3571429 | AC39: =ROUND($AA39*Q39,0) -> 28 | AD39: =ROUND($AA39*R39,0) -> 59 | AE39: =ROUND($AA39*S39,0) -> 31 | AF39: =ROUND($AA39*T39,0) -> 19 | AG39: =ROUND($AA39*U39,0) -> 24 | AH39: =ROUND($AA39*V39,0) -> 21 | AI39: =ROUND($AA39*W39,0) -> 31 | AJ39: =ROUND($AA39*X39,0) -> 45 | AK39: =ROUND($AA39*Y39,0) -> 40 | AL39: =SUM(AC39:AK39) -> 298
D40: 1368 | E40: 2057 | F40: 15 | G40: 24 | H40: 20 | I40: 28 | J40: 75 | K40: 18 | L40: 13 | M40: 13 | N40: 52 | O40: =SUM(F40:N40) -> 258 | Q40: ='X,Y restore'!G40 -> 15 | R40: ='X,Y restore'!H40 -> 10 | S40: ='X,Y restore'!I40 -> 20 | T40: ='X,Y restore'!AI40 -> 8 | U40: ='X,Y restore'!AG40 -> 7 | V40: ='X,Y restore'!AJ40 -> 8 | W40: ='X,Y restore'!M40 -> 13 | X40: ='X,Y restore'!N40 -> 13 | Y40: ='X,Y restore'!O40 -> 24 | Z40: =SUM(Q40:Y40) -> 118 | AA40: =O40/Z40 -> 2.1864407 | AC40: =ROUND($AA40*Q40,0) -> 33 | AD40: =ROUND($AA40*R40,0) -> 22 | AE40: =ROUND($AA40*S40,0) -> 44 | AF40: =ROUND($AA40*T40,0) -> 17 | AG40: =ROUND($AA40*U40,0) -> 15 | AH40: =ROUND($AA40*V40,0) -> 17 | AI40: =ROUND($AA40*W40,0) -> 28 | AJ40: =ROUND($AA40*X40,0) -> 28 | AK40: =ROUND($AA40*Y40,0) -> 52 | AL40: =SUM(AC40:AK40) -> 256
...

Sheet Culled Precincts
A1: Reason | B1: P | C1: R | D1: A1 | E1: A2 | F1: A3 | G1: B1 | H1: B2 | I1: B3 | J1: C1 | K1: C2 | L1: C3
A2: (1-x1)<40% | B2: 2080 | C2: 490 | D2: 8 | E2: 7 | F2: 27 | G2: 35 | H2: 32 | I2: 27 | J2: 15 | K2: 15 | L2: 5
B3: 2473 | C3: 2286 | D3: 30 | E3: 57 | F3: 124 | G3: 118 | H3: 163 | I3: 341 | J3: 24 | K3: 80 | L3: 42
B4: 3605 | C4: 658 | D4: 6 | E4: 10 | F4: 37 | G4: 13 | H4: 30 | I4: 46 | J4: 0 | K4: 21 | L4: 13
B5: 6487 | C5: 1116 | D5: 6 | E5: 25 | F5: 41 | G5: 8 | H5: 69 | I5: 87 | J5: 2 | K5: 27 | L5: 27
B6: 6685 | C6: 1242 | D6: 23 | E6: 27 | F6: 47 | G6: 39 | H6: 96 | I6: 62 | J6: 9 | K6: 21 | L6: 21

Sheet X1,Y1 Restoration; Discard
A1: Variable Name | B1: Value | C1: Cull 1 | D1: P | E1: R | F1: A1 | G1: A2 | H1: A3 | I1: B1 | J1: B2 | K1: B3 | L1: C1 | M1: C2 | N1: C3 | O1: 1-Y1 | P1: 1-X1
A2: P | B2: Precinct Name | C2: 0 | D2: 1000 | E2: 640 | F2: 15 | G2: 14 | H2: 2 | I2: 42 | J2: 66 | K2: 15 | L2: 14 | M2: 6 | N2: 27 | O2: =M2/(M2+G2) -> 0.3 | P2: =(L2+N2)/(F2+H2+L2+N2) -> 0.70689655
A3: R | B3: Registered | C3: 0 | D3: 1001 | E3: 1053 | F3: 15 | G3: 22 | H3: 14 | I3: 37 | J3: 76 | K3: 22 | L3: 14 | M3: 11 | N3: 23 | O3: =M3/(M3+G3) -> 0.33333333 | P3: =(L3+N3)/(F3+H3+L3+N3) -> 0.56060606
A4: A1 | B4: Hyt Early | C4: 0 | D4: 1004 | E4: 1917 | F4: 7 | G4: 17 | H4: 9 | I4: 21 | J4: 72 | K4: 24 | L4: 6 | M4: 11 | N4: 63 | O4: =M4/(M4+G4) -> 0.39285714 | P4: =(L4+N4)/(F4+H4+L4+N4) -> 0.81176471
A5: A2 | B5: Hyt Mail | C5: 0 | D5: 1005 | E5: 1599 | F5: 14 | G5: 26 | H5: 11 | I5: 65 | J5: 130 | K5: 29 | L5: 27 | M5: 10 | N5: 62 | O5: =M5/(M5+G5) -> 0.27777778 | P5: =(L5+N5)/(F5+H5+L5+N5) -> 0.78070175
A6: A3 | B6: Hyt EDV | C6: 0 | D6: 1006 | E6: 1548 | F6: 5 | G6: 27 | H6: 6 | I6: 33 | J6: 68 | K6: 27 | L6: 16 | M6: 6 | N6: 39 | O6: =M6/(M6+G6) -> 0.18181818 | P6: =(L6+N6)/(F6+H6+L6+N6) -> 0.83333333
A7: B1 | B7: McMahill Early | C7: 0 | D7: 1007 | E7: 2681 | F7: 14 | G7: 24 | H7: 9 | I7: 36 | J7: 102 | K7: 33 | L7: 17 | M7: 15 | N7: 47 | O7: =M7/(M7+G7) -> 0.38461538 | P7: =(L7+N7)/(F7+H7+L7+N7) -> 0.73563218
A8: B2 | B8: McMahill Mail | C8: 0 | D8: 1008 | E8: 3439 | F8: 15 | G8: 38 | H8: 25 | I8: 65 | J8: 139 | K8: 35 | L8: 27 | M8: 16 | N8: 64 | O8: =M8/(M8+G8) -> 0.2962963 | P8: =(L8+N8)/(F8+H8+L8+N8) -> 0.69465649
A9: B3 | B9: McMahill EDV | C9: 0 | D9: 1009 | E9: 1380 | F9: 23 | G9: 25 | H9: 29 | I9: 67 | J9: 118 | K9: 46 | L9: 24 | M9: 21 | N9: 51 | O9: =M9/(M9+G9) -> 0.45652174 | P9: =(L9+N9)/(F9+H9+L9+N9) -> 0.59055118
A10: C1 | B10: Roberts Early | C10: 0 | D10: 1012 | E10: 1883 | F10: 23 | G10: 57 | H10: 28 | I10: 82 | J10: 244 | K10: 69 | L10: 35 | M10: 22 | N10: 121 | O10: =M10/(M10+G10) -> 0.27848101 | P10: =(L10+N10)/(F10+H10+L10+N10) -> 0.75362319
A11: C2 | B11: Roberts Mail | C11: 0 | D11: 1015 | E11: 2510 | F11: 34 | G11: 48 | H11: 19 | I11: 69 | J11: 155 | K11: 42 | L11: 14 | M11: 20 | N11: 78 | O11: =M11/(M11+G11) -> 0.29411765 | P11: =(L11+N11)/(F11+H11+L11+N11) -> 0.63448276
A12: C3 | B12: Roberts EDV | C12: 0 | D12: 1016 | E12: 485 | F12: 4 | G12: 15 | H12: 12 | I12: 21 | J12: 47 | K12: 17 | L12: 7 | M12: 2 | N12: 28 | O12: =M12/(M12+G12) -> 0.11764706 | P12: =(L12+N12)/(F12+H12+L12+N12) -> 0.68627451
C13: 0 | D13: 1038 | E13: 2098 | F13: 14 | G13: 38 | H13: 10 | I13: 59 | J13: 120 | K13: 27 | L13: 13 | M13: 9 | N13: 49 | O13: =M13/(M13+G13) -> 0.19148936 | P13: =(L13+N13)/(F13+H13+L13+N13) -> 0.72093023
C14: 0 | D14: 1039 | E14: 3242 | F14: 27 | G14: 74 | H14: 33 | I14: 143 | J14: 271 | K14: 73 | L14: 38 | M14: 22 | N14: 116 | O14: =M14/(M14+G14) -> 0.22916667 | P14: =(L14+N14)/(F14+H14+L14+N14) -> 0.71962617
A15: cos(-45)=n1 | B15: 0.70710678 | C15: 0 | D15: 1063 | E15: 1412 | F15: 12 | G15: 27 | H15: 24 | I15: 49 | J15: 115 | K15: 48 | L15: 21 | M15: 7 | N15: 46 | O15: =M15/(M15+G15) -> 0.20588235 | P15: =(L15+N15)/(F15+H15+L15+N15) -> 0.65048544
A16: sin(-45)=n2 | B16: -0.70710678 | C16: 0 | D16: 1074 | E16: 2203 | F16: 6 | G16: 47 | H16: 20 | I16: 37 | J16: 230 | K16: 77 | L16: 11 | M16: 19 | N16: 84 | O16: =M16/(M16+G16) -> 0.28787879 | P16: =(L16+N16)/(F16+H16+L16+N16) -> 0.78512397
C17: 0 | D17: 1302 | E17: 3655 | F17: 32 | G17: 42 | H17: 14 | I17: 85 | J17: 232 | K17: 60 | L17: 31 | M17: 38 | N17: 81 | O17: =M17/(M17+G17) -> 0.475 | P17: =(L17+N17)/(F17+H17+L17+N17) -> 0.70886076
C18: 0 | D18: 1304 | E18: 2660 | F18: 19 | G18: 40 | H18: 30 | I18: 53 | J18: 145 | K18: 35 | L18: 28 | M18: 13 | N18: 64 | O18: =M18/(M18+G18) -> 0.24528302 | P18: =(L18+N18)/(F18+H18+L18+N18) -> 0.65248227
C19: 0 | D19: 1307 | E19: 2027 | F19: 29 | G19: 30 | H19: 27 | I19: 66 | J19: 142 | K19: 44 | L19: 18 | M19: 18 | N19: 63 | O19: =M19/(M19+G19) -> 0.375 | P19: =(L19+N19)/(F19+H19+L19+N19) -> 0.59124088
C20: 0 | D20: 1318 | E20: 1739 | F20: 14 | G20: 20 | H20: 12 | I20: 29 | J20: 71 | K20: 29 | L20: 5 | M20: 6 | N20: 28 | O20: =M20/(M20+G20) -> 0.23076923 | P20: =(L20+N20)/(F20+H20+L20+N20) -> 0.55932203
C21: 0 | D21: 1327 | E21: 2196 | F21: 19 | G21: 22 | H21: 15 | I21: 33 | J21: 85 | K21: 23 | L21: 18 | M21: 13 | N21: 36 | O21: =M21/(M21+G21) -> 0.37142857 | P21: =(L21+N21)/(F21+H21+L21+N21) -> 0.61363636
C22: 0 | D22: 1328 | E22: 1757 | F22: 11 | G22: 22 | H22: 13 | I22: 38 | J22: 105 | K22: 25 | L22: 20 | M22: 8 | N22: 45 | O22: =M22/(M22+G22) -> 0.26666667 | P22: =(L22+N22)/(F22+H22+L22+N22) -> 0.73033708
C23: 0 | D23: 1330 | E23: 1937 | F23: 27 | G23: 41 | H23: 29 | I23: 69 | J23: 130 | K23: 66 | L23: 21 | M23: 12 | N23: 43 | O23: =M23/(M23+G23) -> 0.22641509 | P23: =(L23+N23)/(F23+H23+L23+N23) -> 0.53333333
C24: 0 | D24: 1331 | E24: 1777 | F24: 11 | G24: 30 | H24: 24 | I24: 27 | J24: 86 | K24: 31 | L24: 11 | M24: 6 | N24: 44 | O24: =M24/(M24+G24) -> 0.16666667 | P24: =(L24+N24)/(F24+H24+L24+N24) -> 0.61111111
C25: 0 | D25: 1333 | E25: 1478 | F25: 19 | G25: 36 | H25: 17 | I25: 50 | J25: 82 | K25: 37 | L25: 11 | M25: 19 | N25: 39 | O25: =M25/(M25+G25) -> 0.34545455 | P25: =(L25+N25)/(F25+H25+L25+N25) -> 0.58139535
C26: 0 | D26: 1334 | E26: 1815 | F26: 17 | G26: 31 | H26: 18 | I26: 52 | J26: 117 | K26: 29 | L26: 14 | M26: 11 | N26: 39 | O26: =M26/(M26+G26) -> 0.26190476 | P26: =(L26+N26)/(F26+H26+L26+N26) -> 0.60227273
C27: 0 | D27: 1335 | E27: 1591 | F27: 11 | G27: 30 | H27: 27 | I27: 57 | J27: 121 | K27: 34 | L27: 12 | M27: 16 | N27: 59 | O27: =M27/(M27+G27) -> 0.34782609 | P27: =(L27+N27)/(F27+H27+L27+N27) -> 0.65137615
C28: 0 | D28: 1336 | E28: 1443 | F28: 17 | G28: 34 | H28: 7 | I28: 26 | J28: 80 | K28: 10 | L28: 7 | M28: 10 | N28: 44 | O28: =M28/(M28+G28) -> 0.22727273 | P28: =(L28+N28)/(F28+H28+L28+N28) -> 0.68
... C594: 0 | D594: 7730 | E594: 2494 | F594: 12 | G594: 52 | H594: 43 | I594: 62 | J594: 208 | K594: 47 | L594: 31 | M594: 18 | N594: 95 | O594: =M594/(M594+G594) -> 0.25714286 | P594: =(L594+N594)/(F594+H594+L594+N594) -> 0.6961326

Sheet M1,M2,M3 Restoration
A1: Variable Name | B1: Value | C1: Cull 1 | D1: Operators | E1: Values | F1: P | G1: A1 | H1: A3 | I1: B1 | J1: B3 | K1: C1 | L1: C3 | M1: M1,1 | N1: M2,1 | O1: M3,1 | P1: Expected m2,1 | Q1: Expected m3,1 | R1: u0,1 | S1: v0,1 | T1: w0,1 | U1: u0,1 | V1: v1,1 | W1: w1,1 | X1: Theta 1 | Y1: Theta 2 | Z1: u1,1 | AA1: v2,1 | AB1: w1,1 | AC1: Phi 1 | AD1: Phi 2 | AE1: u2,1 | AF1: v2,1 | AG1: w2,1 | AH1: r2,1 | AI1: r3,1 | AJ1: r2,2 | AK1: r3,2 | AL1: u3,1 | AM1: v3,1 | AN1: w3,1 | AO1: Great Scale | AP1: Inter M1,2 | AQ1: Inter M2,2 | AR1: Inter M3,2 | AS1: M1,2 | AT1: M2,2 | AU1: M3,2
A2: A1 | B2: Hyt Early | C2: 0 | F2: 1000 | G2: 15 | H2: 2 | I2: 42 | J2: 15 | K2: 14 | L2: 27 | M2: =G2/(G2+H2) -> 0.88235294 | N2: =I2/(I2+J2) -> 0.73684211 | O2: =K2/(K2+L2) -> 0.34146341 | P2: =$E$3+$E$4*M2+$E$5*M2*M2 -> 0.67268339 | Q2: =$E$7+$E$8*M2+$E$9*M2*M2 -> 0.29488235 | R2: =M2 -> 0.88235294 | S2: =N2 -> 0.73684211 | T2: =O2 -> 0.34146341 | U2: =R2 -> 0.88235294 | V2: =S2-$E$3 -> 0.29484211 | W2: =T2-$E$7 -> 0.12246341 | X2: =ATAN2(U2,V2) -> 0.32248932 | Y2: =$E$11-X2 -> 0.46290884 | Z2: =U2*COS(Y2)-V2*SIN(Y2) -> 0.65782923 | AA2: =U2*SIN(Y2)+V2*COS(Y2) -> 0.65782923 | AB2: =W2 -> 0.12246341 | AC2: =ATAN2(Z2,AB2) -> 0.18405598 | AD2: =$E$11-AC2 -> 0.60134219 | AE2: =Z2*COS(AD2)-AB2*SIN(AD2) -> 0.47314722 | AF2: =AE2 -> 0.47314722 | AG2: =Z2*SIN(AD2)+AB2*COS(AD2) -> 0.47314722 | AH2: =N2-P2 -> 0.064158714 | AI2: =O2-Q2 -> 0.046581062 | AJ2: =AH2*$E$17 -> 0.038356488 | AK2: =AI2*$E$18 -> 0.02768588 | AL2: =AE2 -> 0.47314722 | AM2: =AF2+AJ2 -> 0.5115037 | AN2: =AG2+AK2 -> 0.5008331 | AO2: =M2/AL2 -> 1.8648592 | AP2: =AL2*$AO2 -> 0.88235294 | AQ2: =AM2*$AO2 -> 0.95388239 | AR2: =AN2*$AO2 -> 0.93398321 | AS2: =IF(AP2<0,0,IF(AP2>1,1,AP2)) -> 0.88235294 | AT2: =IF(AQ2<0,0,IF(AQ2>1,1,AQ2)) -> 0.95388239 | AU2: =IF(AR2<0,0,IF(AR2>1,1,AR2)) -> 0.93398321
A3: A2 | B3: Hyt Mail | C3: 0 | D3: k0 | E3: 0.442 | F3: 1001 | G3: 15 | H3: 14 | I3: 37 | J3: 22 | K3: 14 | L3: 23 | M3: =G3/(G3+H3) -> 0.51724138 | N3: =I3/(I3+J3) -> 0.62711864 | O3: =K3/(K3+L3) -> 0.37837838 | P3: =$E$3+$E$4*M3+$E$5*M3*M3 -> 0.57777586 | Q3: =$E$7+$E$8*M3+$E$9*M3*M3 -> 0.27568252 | R3: =M3 -> 0.51724138 | S3: =N3 -> 0.62711864 | T3: =O3 -> 0.37837838 | U3: =R3 -> 0.51724138 | V3: =S3-$E$3 -> 0.18511864 | W3: =T3-$E$7 -> 0.15937838 | X3: =ATAN2(U3,V3) -> 0.34369177 | Y3: =$E$11-X3 -> 0.4417064 | Z3: =U3*COS(Y3)-V3*SIN(Y3) -> 0.38846336 | AA3: =U3*SIN(Y3)+V3*COS(Y3) -> 0.38846336 | AB3: =W3 -> 0.15937838 | AC3: =ATAN2(Z3,AB3) -> 0.3893361 | AD3: =$E$11-AC3 -> 0.39606206 | AE3: =Z3*COS(AD3)-AB3*SIN(AD3) -> 0.29690507 | AF3: =AE3 -> 0.29690507 | AG3: =Z3*SIN(AD3)+AB3*COS(AD3) -> 0.29690507 | AH3: =N3-P3 -> 0.049342782 | AI3: =O3-Q3 -> 0.10269586 | AJ3: =AH3*$E$17 -> 0.029498967 | AK3: =AI3*$E$18 -> 0.061038222 | AL3: =AE3 -> 0.29690507 | AM3: =AF3+AJ3 -> 0.32640404 | AN3: =AG3+AK3 -> 0.3579433 | AO3: =M3/AL3 -> 1.7421103 | AP3: =AL3*$AO3 -> 0.51724138 | AQ3: =AM3*$AO3 -> 0.56863183 | AR3: =AN3*$AO3 -> 0.62357669 | AS3: =IF(AP3<0,0,IF(AP3>1,1,AP3)) -> 0.51724138 | AT3: =IF(AQ3<0,0,IF(AQ3>1,1,AQ3)) -> 0.56863183 | AU3: =IF(AR3<0,0,IF(AR3>1,1,AR3)) -> 0.62357669
A4: A3 | B4: Hyt EDV | C4: 0 | D4: k1 | E4: 0.264 | F4: 1004 | G4: 7 | H4: 9 | I4: 21 | J4: 24 | K4: 6 | L4: 63 | M4: =G4/(G4+H4) -> 0.4375 | N4: =I4/(I4+J4) -> 0.46666667 | O4: =K4/(K4+L4) -> 0.086956522 | P4: =$E$3+$E$4*M4+$E$5*M4*M4 -> 0.55694492 | Q4: =$E$7+$E$8*M4+$E$9*M4*M4 -> 0.26919766 | R4: =M4 -> 0.4375 | S4: =N4 -> 0.46666667 | T4: =O4 -> 0.086956522 | U4: =R4 -> 0.4375 | V4: =S4-$E$3 -> 0.024666667 | W4: =T4-$E$7 -> -0.13204348 | X4: =ATAN2(U4,V4) -> 0.056321325 | Y4: =$E$11-X4 -> 0.72907684 | Z4: =U4*COS(Y4)-V4*SIN(Y4) -> 0.30985052 | AA4: =U4*SIN(Y4)+V4*COS(Y4) -> 0.30985052 | AB4: =W4 -> -0.13204348 | AC4: =ATAN2(Z4,AB4) -> -0.40284615 | AD4: =$E$11-AC4 -> 1.1882443 | AE4: =Z4*COS(AD4)-AB4*SIN(AD4) -> 0.23816258 | AF4: =AE4 -> 0.23816258 | AG4: =Z4*SIN(AD4)+AB4*COS(AD4) -> 0.23816258 | AH4: =N4-P4 -> -0.090278255 | AI4: =O4-Q4 -> -0.18224113 | AJ4: =AH4*$E$17 -> -0.05397173 | AK4: =AI4*$E$18 -> -0.10831668 | AL4: =AE4 -> 0.23816258 | AM4: =AF4+AJ4 -> 0.18419085 | AN4: =AG4+AK4 -> 0.12984589 | AO4: =M4/AL4 -> 1.8369804 | AP4: =AL4*$AO4 -> 0.4375 | AQ4: =AM4*$AO4 -> 0.33835499 | AR4: =AN4*$AO4 -> 0.23852437 | AS4: =IF(AP4<0,0,IF(AP4>1,1,AP4)) -> 0.4375 | AT4: =IF(AQ4<0,0,IF(AQ4>1,1,AQ4)) -> 0.33835499 | AU4: =IF(AR4<0,0,IF(AR4>1,1,AR4)) -> 0.23852437
A5: B1 | B5: McMahill Early | C5: 0 | D5: k2 | E5: -0.0029 | F5: 1005 | G5: 14 | H5: 11 | I5: 65 | J5: 29 | K5: 27 | L5: 62 | M5: =G5/(G5+H5) -> 0.56 | N5: =I5/(I5+J5) -> 0.69148936 | O5: =K5/(K5+L5) -> 0.30337079 | P5: =$E$3+$E$4*M5+$E$5*M5*M5 -> 0.58893056 | Q5: =$E$7+$E$8*M5+$E$9*M5*M5 -> 0.27882144 | R5: =M5 -> 0.56 | S5: =N5 -> 0.69148936 | T5: =O5 -> 0.30337079 | U5: =R5 -> 0.56 | V5: =S5-$E$3 -> 0.24948936 | W5: =T5-$E$7 -> 0.084370787 | X5: =ATAN2(U5,V5) -> 0.41911938 | Y5: =$E$11-X5 -> 0.36627879 | Z5: =U5*COS(Y5)-V5*SIN(Y5) -> 0.43350025 | AA5: =U5*SIN(Y5)+V5*COS(Y5) -> 0.43350025 | AB5: =W5 -> 0.084370787 | AC5: =ATAN2(Z5,AB5) -> 0.19222377 | AD5: =$E$11-AC5 -> 0.5931744 | AE5: =Z5*COS(AD5)-AB5*SIN(AD5) -> 0.31228264 | AF5: =AE5 -> 0.31228264 | AG5: =Z5*SIN(AD5)+AB5*COS(AD5) -> 0.31228264 | AH5: =N5-P5 -> 0.1025588 | AI5: =O5-Q5 -> 0.024549347 | AJ5: =AH5*$E$17 -> 0.061313502 | AK5: =AI5*$E$18 -> 0.014591129 | AL5: =AE5 -> 0.31228264 | AM5: =AF5+AJ5 -> 0.37359615 | AN5: =AG5+AK5 -> 0.32687377 | AO5: =M5/AL5 -> 1.7932473 | AP5: =AL5*$AO5 -> 0.56 | AQ5: =AM5*$AO5 -> 0.66995027 | AR5: =AN5*$AO5 -> 0.5861655 | AS5: =IF(AP5<0,0,IF(AP5>1,1,AP5)) -> 0.56 | AT5: =IF(AQ5<0,0,IF(AQ5>1,1,AQ5)) -> 0.66995027 | AU5: =IF(AR5<0,0,IF(AR5>1,1,AR5)) -> 0.5861655
A6: B2 | B6: McMahill Mail | C6: 0 | F6: 1006 | G6: 5 | H6: 6 | I6: 33 | J6: 27 | K6: 16 | L6: 39 | M6: =G6/(G6+H6) -> 0.45454545 | N6: =I6/(I6+J6) -> 0.55 | O6: =K6/(K6+L6) -> 0.29090909 | P6: =$E$3+$E$4*M6+$E$5*M6*M6 -> 0.56140083 | Q6: =$E$7+$E$8*M6+$E$9*M6*M6 -> 0.27065289 | R6: =M6 -> 0.45454545 | S6: =N6 -> 0.55 | T6: =O6 -> 0.29090909 | U6: =R6 -> 0.45454545 | V6: =S6-$E$3 -> 0.108 | W6: =T6-$E$7 -> 0.071909091 | X6: =ATAN2(U6,V6) -> 0.23327446 | Y6: =$E$11-X6 -> 0.5521237 | Z6: =U6*COS(Y6)-V6*SIN(Y6) -> 0.33036008 | AA6: =U6*SIN(Y6)+V6*COS(Y6) -> 0.33036008 | AB6: =W6 -> 0.071909091 | AC6: =ATAN2(Z6,AB6) -> 0.21432566 | AD6: =$E$11-AC6 -> 0.5710725 | AE6: =Z6*COS(AD6)-AB6*SIN(AD6) -> 0.23906976 | AF6: =AE6 -> 0.23906976 | AG6: =Z6*SIN(AD6)+AB6*COS(AD6) -> 0.23906976 | AH6: =N6-P6 -> -0.011400826 | AI6: =O6-Q6 -> 0.020256198 | AJ6: =AH6*$E$17 -> -0.006815842 | AK6: =AI6*$E$18 -> 0.012039457 | AL6: =AE6 -> 0.23906976 | AM6: =AF6+AJ6 -> 0.23225392 | AN6: =AG6+AK6 -> 0.25110922 | AO6: =M6/AL6 -> 1.9013088 | AP6: =AL6*$AO6 -> 0.45454545 | AQ6: =AM6*$AO6 -> 0.44158643 | AR6: =AN6*$AO6 -> 0.47743618 | AS6: =IF(AP6<0,0,IF(AP6>1,1,AP6)) -> 0.45454545 | AT6: =IF(AQ6<0,0,IF(AQ6>1,1,AQ6)) -> 0.44158643 | AU6: =IF(AR6<0,0,IF(AR6>1,1,AR6)) -> 0.47743618
A7: B3 | B7: McMahill EDV | C7: 0 | D7: c0 | E7: 0.219 | F7: 1007 | G7: 14 | H7: 9 | I7: 36 | J7: 33 | K7: 17 | L7: 47 | M7: =G7/(G7+H7) -> 0.60869565 | N7: =I7/(I7+J7) -> 0.52173913 | O7: =K7/(K7+L7) -> 0.265625 | P7: =$E$3+$E$4*M7+$E$5*M7*M7 -> 0.60162117 | Q7: =$E$7+$E$8*M7+$E$9*M7*M7 -> 0.28210851 | R7: =M7 -> 0.60869565 | S7: =N7 -> 0.52173913 | T7: =O7 -> 0.265625 | U7: =R7 -> 0.60869565 | V7: =S7-$E$3 -> 0.07973913 | W7: =T7-$E$7 -> 0.046625 | X7: =ATAN2(U7,V7) -> 0.13025826 | Y7: =$E$11-X7 -> 0.6551399 | Z7: =U7*COS(Y7)-V7*SIN(Y7) -> 0.43409027 | AA7: =U7*SIN(Y7)+V7*COS(Y7) -> 0.43409027 | AB7: =W7 -> 0.046625 | AC7: =ATAN2(Z7,AB7) -> 0.10699833 | AD7: =$E$11-AC7 -> 0.67839984 | AE7: =Z7*COS(AD7)-AB7*SIN(AD7) -> 0.30871366 | AF7: =AE7 -> 0.30871366 | AG7: =Z7*SIN(AD7)+AB7*COS(AD7) -> 0.30871366 | AH7: =N7-P7 -> -0.079882042 | AI7: =O7-Q7 -> -0.016483507 | AJ7: =AH7*$E$17 -> -0.047756483 | AK7: =AI7*$E$18 -> -0.0097971229 | AL7: =AE7 -> 0.30871366 | AM7: =AF7+AJ7 -> 0.26095718 | AN7: =AG7+AK7 -> 0.29891654 | AO7: =M7/AL7 -> 1.9717159 | AP7: =AL7*$AO7 -> 0.60869565 | AQ7: =AM7*$AO7 -> 0.51453343 | AR7: =AN7*$AO7 -> 0.58937851 | AS7: =IF(AP7<0,0,IF(AP7>1,1,AP7)) -> 0.60869565 | AT7: =IF(AQ7<0,0,IF(AQ7>1,1,AQ7)) -> 0.51453343 | AU7: =IF(AR7<0,0,IF(AR7>1,1,AR7)) -> 0.58937851
A8: C1 | B8: Roberts Early | C8: 0 | D8: c1 | E8: 0.143 | F8: 1008 | G8: 15 | H8: 25 | I8: 65 | J8: 35 | K8: 27 | L8: 64 | M8: =G8/(G8+H8) -> 0.375 | N8: =I8/(I8+J8) -> 0.65 | O8: =K8/(K8+L8) -> 0.2967033 | P8: =$E$3+$E$4*M8+$E$5*M8*M8 -> 0.54059219 | Q8: =$E$7+$E$8*M8+$E$9*M8*M8 -> 0.26354062 | R8: =M8 -> 0.375 | S8: =N8 -> 0.65 | T8: =O8 -> 0.2967033 | U8: =R8 -> 0.375 | V8: =S8-$E$3 -> 0.208 | W8: =T8-$E$7 -> 0.077703297 | X8: =ATAN2(U8,V8) -> 0.506419 | Y8: =$E$11-X8 -> 0.27897916 | Z8: =U8*COS(Y8)-V8*SIN(Y8) -> 0.30322351 | AA8: =U8*SIN(Y8)+V8*COS(Y8) -> 0.30322351 | AB8: =W8 -> 0.077703297 | AC8: =ATAN2(Z8,AB8) -> 0.25085934 | AD8: =$E$11-AC8 -> 0.53453882 | AE8: =Z8*COS(AD8)-AB8*SIN(AD8) -> 0.22133945 | AF8: =AE8 -> 0.22133945 | AG8: =Z8*SIN(AD8)+AB8*COS(AD8) -> 0.22133945 | AH8: =N8-P8 -> 0.10940781 | AI8: =O8-Q8 -> 0.033162672 | AJ8: =AH8*$E$17 -> 0.065408098 | AK8: =AI8*$E$18 -> 0.019710537 | AL8: =AE8 -> 0.22133945 | AM8: =AF8+AJ8 -> 0.28674755 | AN8: =AG8+AK8 -> 0.24104998 | AO8: =M8/AL8 -> 1.6942303 | AP8: =AL8*$AO8 -> 0.375 | AQ8: =AM8*$AO8 -> 0.48581638 | AR8: =AN8*$AO8 -> 0.40839419 | AS8: =IF(AP8<0,0,IF(AP8>1,1,AP8)) -> 0.375 | AT8: =IF(AQ8<0,0,IF(AQ8>1,1,AQ8)) -> 0.48581638 | AU8: =IF(AR8<0,0,IF(AR8>1,1,AR8)) -> 0.40839419
A9: C2 | B9: Roberts Mail | C9: 0 | D9: c2 | E9: -0.0646 | F9: 1009 | G9: 23 | H9: 29 | I9: 67 | J9: 46 | K9: 24 | L9: 51 | M9: =G9/(G9+H9) -> 0.44230769 | N9: =I9/(I9+J9) -> 0.59292035 | O9: =K9/(K9+L9) -> 0.32 | P9: =$E$3+$E$4*M9+$E$5*M9*M9 -> 0.55820189 | Q9: =$E$7+$E$8*M9+$E$9*M9*M9 -> 0.26961191 | R9: =M9 -> 0.44230769 | S9: =N9 -> 0.59292035 | T9: =O9 -> 0.32 | U9: =R9 -> 0.44230769 | V9: =S9-$E$3 -> 0.15092035 | W9: =T9-$E$7 -> 0.101 | X9: =ATAN2(U9,V9) -> 0.32882383 | Y9: =$E$11-X9 -> 0.45657433 | Z9: =U9*COS(Y9)-V9*SIN(Y9) -> 0.3304641 | AA9: =U9*SIN(Y9)+V9*COS(Y9) -> 0.3304641 | AB9: =W9 -> 0.101 | AC9: =ATAN2(Z9,AB9) -> 0.2966146 | AD9: =$E$11-AC9 -> 0.48878356 | AE9: =Z9*COS(AD9)-AB9*SIN(AD9) -> 0.24434353 | AF9: =AE9 -> 0.24434353 | AG9: =Z9*SIN(AD9)+AB9*COS(AD9) -> 0.24434353 | AH9: =N9-P9 -> 0.034718468 | AI9: =O9-Q9 -> 0.050388092 | AJ9: =AH9*$E$17 -> 0.020756003 | AK9: =AI9*$E$18 -> 0.029948623 | AL9: =AE9 -> 0.24434353 | AM9: =AF9+AJ9 -> 0.26509954 | AN9: =AG9+AK9 -> 0.27429216 | AO9: =M9/AL9 -> 1.8101878 | AP9: =AL9*$AO9 -> 0.44230769 | AQ9: =AM9*$AO9 -> 0.47987996 | AR9: =AN9*$AO9 -> 0.49652033 | AS9: =IF(AP9<0,0,IF(AP9>1,1,AP9)) -> 0.44230769 | AT9: =IF(AQ9<0,0,IF(AQ9>1,1,AQ9)) -> 0.47987996 | AU9: =IF(AR9<0,0,IF(AR9>1,1,AR9)) -> 0.49652033
A10: C3 | B10: Roberts EDV | C10: 0 | F10: 1012 | G10: 23 | H10: 28 | I10: 82 | J10: 69 | K10: 35 | L10: 121 | M10: =G10/(G10+H10) -> 0.45098039 | N10: =I10/(I10+J10) -> 0.54304636 | O10: =K10/(K10+L10) -> 0.22435897 | P10: =$E$3+$E$4*M10+$E$5*M10*M10 -> 0.56046901 | Q10: =$E$7+$E$8*M10+$E$9*M10*M10 -> 0.27035163 | R10: =M10 -> 0.45098039 | S10: =N10 -> 0.54304636 | T10: =O10 -> 0.22435897 | U10: =R10 -> 0.45098039 | V10: =S10-$E$3 -> 0.10104636 | W10: =T10-$E$7 -> 0.0053589744 | X10: =ATAN2(U10,V10) -> 0.2204189 | Y10: =$E$11-X10 -> 0.56497926 | Z10: =U10*COS(Y10)-V10*SIN(Y10) -> 0.32679786 | AA10: =U10*SIN(Y10)+V10*COS(Y10) -> 0.32679786 | AB10: =W10 -> 0.0053589744 | AC10: =ATAN2(Z10,AB10) -> 0.016396968 | AD10: =$E$11-AC10 -> 0.7690012 | AE10: =Z10*COS(AD10)-AB10*SIN(AD10) -> 0.23111205 | AF10: =AE10 -> 0.23111205 | AG10: =Z10*SIN(AD10)+AB10*COS(AD10) -> 0.23111205 | AH10: =N10-P10 -> -0.017422654 | AI10: =O10-Q10 -> -0.04599266 | AJ10: =AH10*$E$17 -> -0.010415917 | AK10: =AI10*$E$18 -> -0.027336158 | AL10: =AE10 -> 0.23111205 | AM10: =AF10+AJ10 -> 0.22069613 | AN10: =AG10+AK10 -> 0.20377589 | AO10: =M10/AL10 -> 1.9513495 | AP10: =AL10*$AO10 -> 0.45098039 | AQ10: =AM10*$AO10 -> 0.4306553 | AR10: =AN10*$AO10 -> 0.39763799 | AS10: =IF(AP10<0,0,IF(AP10>1,1,AP10)) -> 0.45098039 | AT10: =IF(AQ10<0,0,IF(AQ10>1,1,AQ10)) -> 0.4306553 | AU10: =IF(AR10<0,0,IF(AR10>1,1,AR10)) -> 0.39763799
C11: 0 | D11: Pi/4 | E11: =PI()/4 -> 0.78539816 | F11: 1015 | G11: 34 | H11: 19 | I11: 69 | J11: 42 | K11: 14 | L11: 78 | M11: =G11/(G11+H11) -> 0.64150943 | N11: =I11/(I11+J11) -> 0.62162162 | O11: =K11/(K11+L11) -> 0.15217391 | P11: =$E$3+$E$4*M11+$E$5*M11*M11 -> 0.61016504 | Q11: =$E$7+$E$8*M11+$E$9*M11*M11 -> 0.28415073 | R11: =M11 -> 0.64150943 | S11: =N11 -> 0.62162162 | T11: =O11 -> 0.15217391 | U11: =R11 -> 0.64150943 | V11: =S11-$E$3 -> 0.17962162 | W11: =T11-$E$7 -> -0.066826087 | X11: =ATAN2(U11,V11) -> 0.27300723 | Y11: =$E$11-X11 -> 0.51239093 | Z11: =U11*COS(Y11)-V11*SIN(Y11) -> 0.47106172 | AA11: =U11*SIN(Y11)+V11*COS(Y11) -> 0.47106172 | AB11: =W11 -> -0.066826087 | AC11: =ATAN2(Z11,AB11) -> -0.14092237 | AD11: =$E$11-AC11 -> 0.92632053 | AE11: =Z11*COS(AD11)-AB11*SIN(AD11) -> 0.33642597 | AF11: =AE11 -> 0.33642597 | AG11: =Z11*SIN(AD11)+AB11*COS(AD11) -> 0.33642597 | AH11: =N11-P11 -> 0.011456581 | AI11: =O11-Q11 -> -0.13197682 | AJ11: =AH11*$E$17 -> 0.006849174 | AK11: =AI11*$E$18 -> -0.078441628 | AL11: =AE11 -> 0.33642597 | AM11: =AF11+AJ11 -> 0.34327514 | AN11: =AG11+AK11 -> 0.25798434 | AO11: =M11/AL11 -> 1.9068368 | AP11: =AL11*$AO11 -> 0.64150943 | AQ11: =AM11*$AO11 -> 0.65456969 | AR11: =AN11*$AO11 -> 0.49193405 | AS11: =IF(AP11<0,0,IF(AP11>1,1,AP11)) -> 0.64150943 | AT11: =IF(AQ11<0,0,IF(AQ11>1,1,AQ11)) -> 0.65456969 | AU11: =IF(AR11<0,0,IF(AR11>1,1,AR11)) -> 0.49193405
A12: m1 | B12: A1/(A1+A3) | C12: 0 | F12: 1016 | G12: 4 | H12: 12 | I12: 21 | J12: 17 | K12: 7 | L12: 28 | M12: =G12/(G12+H12) -> 0.25 | N12: =I12/(I12+J12) -> 0.55263158 | O12: =K12/(K12+L12) -> 0.2 | P12: =$E$3+$E$4*M12+$E$5*M12*M12 -> 0.50781875 | Q12: =$E$7+$E$8*M12+$E$9*M12*M12 -> 0.2507125 | R12: =M12 -> 0.25 | S12: =N12 -> 0.55263158 | T12: =O12 -> 0.2 | U12: =R12 -> 0.25 | V12: =S12-$E$3 -> 0.11063158 | W12: =T12-$E$7 -> -0.019 | X12: =ATAN2(U12,V12) -> 0.41662145 | Y12: =$E$11-X12 -> 0.36877671 | Z12: =U12*COS(Y12)-V12*SIN(Y12) -> 0.19331237 | AA12: =U12*SIN(Y12)+V12*COS(Y12) -> 0.19331237 | AB12: =W12 -> -0.019 | AC12: =ATAN2(Z12,AB12) -> -0.09797185 | AD12: =$E$11-AC12 -> 0.88337001 | AE12: =Z12*COS(AD12)-AB12*SIN(AD12) -> 0.13735114 | AF12: =AE12 -> 0.13735114 | AG12: =Z12*SIN(AD12)+AB12*COS(AD12) -> 0.13735114 | AH12: =N12-P12 -> 0.044812829 | AI12: =O12-Q12 -> -0.0507125 | AJ12: =AH12*$E$17 -> 0.026790791 | AK12: =AI12*$E$18 -> -0.030141438 | AL12: =AE12 -> 0.13735114 | AM12: =AF12+AJ12 -> 0.16414193 | AN12: =AG12+AK12 -> 0.10720971 | AO12: =M12/AL12 -> 1.8201523 | AP12: =AL12*$AO12 -> 0.25 | AQ12: =AM12*$AO12 -> 0.29876332 | AR12: =AN12*$AO12 -> 0.19513799 | AS12: =IF(AP12<0,0,IF(AP12>1,1,AP12)) -> 0.25 | AT12: =IF(AQ12<0,0,IF(AQ12>1,1,AQ12)) -> 0.29876332 | AU12: =IF(AR12<0,0,IF(AR12>1,1,AR12)) -> 0.19513799
A13: m2 | B13: B1/(B1+B3) | C13: 0 | F13: 1038 | G13: 14 | H13: 10 | I13: 59 | J13: 27 | K13: 13 | L13: 49 | M13: =G13/(G13+H13) -> 0.58333333 | N13: =I13/(I13+J13) -> 0.68604651 | O13: =K13/(K13+L13) -> 0.20967742 | P13: =$E$3+$E$4*M13+$E$5*M13*M13 -> 0.59501319 | Q13: =$E$7+$E$8*M13+$E$9*M13*M13 -> 0.28043472 | R13: =M13 -> 0.58333333 | S13: =N13 -> 0.68604651 | T13: =O13 -> 0.20967742 | U13: =R13 -> 0.58333333 | V13: =S13-$E$3 -> 0.24404651 | W13: =T13-$E$7 -> -0.0093225806 | X13: =ATAN2(U13,V13) -> 0.39623773 | Y13: =$E$11-X13 -> 0.38916043 | Z13: =U13*COS(Y13)-V13*SIN(Y13) -> 0.44712217 | AA13: =U13*SIN(Y13)+V13*COS(Y13) -> 0.44712217 | AB13: =W13 -> -0.0093225806 | AC13: =ATAN2(Z13,AB13) -> -0.020847166 | AD13: =$E$11-AC13 -> 0.80624533 | AE13: =Z13*COS(AD13)-AB13*SIN(AD13) -> 0.31623184 | AF13: =AE13 -> 0.31623184 | AG13: =Z13*SIN(AD13)+AB13*COS(AD13) -> 0.31623184 | AH13: =N13-P13 -> 0.091033317 | AI13: =O13-Q13 -> -0.070757303 | AJ13: =AH13*$E$17 -> 0.054423134 | AK13: =AI13*$E$18 -> -0.04205525 | AL13: =AE13 -> 0.31623184 | AM13: =AF13+AJ13 -> 0.37065497 | AN13: =AG13+AK13 -> 0.27417659 | AO13: =M13/AL13 -> 1.8446382 | AP13: =AL13*$AO13 -> 0.58333333 | AQ13: =AM13*$AO13 -> 0.68372433 | AR13: =AN13*$AO13 -> 0.50575661 | AS13: =IF(AP13<0,0,IF(AP13>1,1,AP13)) -> 0.58333333 | AT13: =IF(AQ13<0,0,IF(AQ13>1,1,AQ13)) -> 0.68372433 | AU13: =IF(AR13<0,0,IF(AR13>1,1,AR13)) -> 0.50575661
